Workbook

Sheet Tender Data
A1: REPORT_DATE | B1: RECORD_ID | C1: TENDER_ID | D1: PUBLICATION_DATE | E1: CLOSING_DATE | F1: CLOSING_TIME | G1: TENDER_TYPE | H1: TENDER_DESCRIPTION | I1: TENDER_SOURCE | J1: DEPARTMENT | K1: PROVINCE | L1: ESUBMISSION | M1: CATEGORY | N1: IS_THERE_A_BRIEFING_SESSION | O1: BRIEFING_DATE | P1: COMPULSORY_BRIEFING | Q1: BRIEFING_SESSION_VENUE | R1: LINK | S1: SOE | T1: COST_OF_SALES_ESTIMATE | U1: CAPABILITY_AVAILABLE | V1: CAPABILITY_GROUP | W1: REQUIREMENTS
A2: 46163 | B2: 192 | C2: RFQ/OBP026/2026/27 | D2: 46160 | E2: 46168 | F2: 12:00 | G2: Request for Quotation | H2: Appointment of a service provider to Upgrade Kaspersky Security Center and End Node Anti-Virus | I2: ETENDERS.GOV.ZA | J2: Onderstepoort Biological Products Limited | K2: Gauteng | L2: No | M2: Services: Professional | N2: No | O2: N/A | P2: No | Q2: N/A | R2: https://www.etenders.gov.za/home/Download/?blobName=22c59f90-f466-44ed-98b2-de07b0485ccc.pdf&downloadedFileName=Solicitation%20ID%20RFQ_OBP026_2026_27%20Request%20for%20Quote%20May%2018%202026%20(1).pdf
A3: 46163 | B3: 191 | C3: ECR/RISK/01/05/2026 | D3: 46160 | E3: 46164 | F3: 12:00 | G3: Request for Quotation | H3: APPOINTMENT OF A SERVICE PROVIDER FOR CALIBRATION AND TRANSPORTATION OF MARK X MACHINES | I3: ETENDERS.GOV.ZA | J3: Passenger Rail Agency of South Africa | K3: Eastern Cape | L3: No | M3: Services: General | N3: Yes | O3: N/A | P3: Yes | Q3: N/A | R3: https://www.etenders.gov.za/home/Download/?blobName=92d5a67d-a91f-4ab5-a075-681ae3ec000e.pdf&downloadedFileName=RFQ%20Risk%20Calibration%20-%20Mark%20X%20Machines.pdf
A4: 46163 | B4: 190 | C4: RFQJW0053SM2026 | D4: 46160 | E4: 46167 | F4: 16:00 | G4: Request for Quotation | H4: Service of meter test equipment at Flow Lab, Ffennel Road Depot | I4: ETENDERS.GOV.ZA | J4: Johannesburg Water | K4: Gauteng | L4: No | M4: Other service activities | N4: No | O4: N/A | P4: No | Q4: N/A | R4: https://www.etenders.gov.za/home/Download/?blobName=2a227aab-ab2d-4962-9ff9-02cdcc1e8b3b.pdf&downloadedFileName=RFQJW0053SM2026%20%E2%80%93%20Service%20of%20meter%20test%20equipment%20at%20Flow%20Lab,%20Ffennell%20Road%20Depot.pdf
A5: 46163 | B5: 189 | C5: NKO 12/2026 | D5: 46160 | E5: 46198 | F5: 12:00 | G5: Request for Bid(Open-Tender) | H5: APPOINTMENT OF A SERVICE PROVIDER FOR THE SUPPLY AND DELIVERY OF TRANSPORT SERVICES TO NKOMAZI LOCAL MUNICIPALITY FOR A PERIOD OF THIRTY-SIX (36) MONTHS | I5: ETENDERS.GOV.ZA | J5: Nkomazi Local Municipality | K5: Mpumalanga | L5: No | M5: Transportation and storage | N5: Yes | O5: 46168 | P5: No | Q5: Municipal Town Hall (Kobwa), Fish Eagle, Malalane | R5: https://www.etenders.gov.za/home/Download/?blobName=e076bf5d-c128-4aeb-bb78-a1529e662e4c.pdf&downloadedFileName=Transport%20(5).pdf
A6: 46163 | B6: 188 | C6: 2026/081 | D6: 46160 | E6: 46191 | F6: 12:00 | G6: Request for Bid(Open-Tender) | H6: APPOINTMENT OF PANEL OF 10 (TEN) PROFESSIONAL SERVICE PROVIDERS FOR IMPLEMENTATION OF UTHUKELA DISTRICT MUNICIPALITY SECTION 63 MINISTERIAL DIRECTIVE FOR A PERIOD OF THREE (3) YEARS. | I6: ETENDERS.GOV.ZA | J6: Umgeni Water | K6: National | L6: No | M6: Services: Professional | N6: Yes | O6: 46171 | P6: Yes | Q6: uMngeni-uThukela Water, Richards Bay Regional Office, Cnr, South Central Arterial & Battery Bank Ric | R6: https://www.etenders.gov.za/home/Download/?blobName=2da0cf9c-b4b6-40e6-807a-8c16c6033212.pdf&downloadedFileName=2026-081%20Attachment%20for%20e-portal%20advert.pdf
A7: 46163 | B7: 187 | C7: SECU 26/010 | D7: 46160 | E7: 46163 | F7: 11:00 | G7: Request for Quotation | H7: DEWETSDORP, HOUSE NUMBER 21, VOORTREKKER STREET: RENDERING OF SECURITY SERVICES ON A MONTH-TO-MONTH BASIS FOR A PERIOD NOT EXCEEDING SIX (6) MONTHS | I7: ETENDERS.GOV.ZA | J7: Public Works | K7: Free State | L7: No | M7: Security and investigation activities | N7: No | O7: N/A | P7: No | Q7: N/A | R7: https://www.etenders.gov.za/home/Download/?blobName=d4077650-9f17-4113-9f64-519872f2bd1e.pdf&downloadedFileName=SECU%2026-010%20DOCUMENT.pdf
A8: 46163 | B8: 186 | C8: IFA/CONTRACTOR/TMT/EC/2026/1 | D8: 46160 | E8: 46181 | F8: 11:00 | G8: Expression of interest | H8: INVITATION FOR AN EOI TO REGISTER ON TMT INFRASTRUCTURE FRAMEWORK AGREEMENT FOR A PERIOD OF 3 YEARS FROM THE CONSTRUCTION INDUSTRY DEVELOPMENT BOARD (CIDB) REGISTERED CONTRACTORS IN THE FOLLOWING CLASS OF WORKS CATEGORIES • GB - General Building • CE - Civil Engineering • ME - Mechanical Engineering • EB - Electrical installations for buildings • SO - Water supply and drainage for buildings (wet services, plumbing) • SQ - Steel security fencing or precast concrete | I8: ETENDERS.GOV.ZA | J8: THE MVULA TRUST | K8: Eastern Cape | L8: No | M8: Construction | N8: No | O8: N/A | P8: No | Q8: N/A | R8: https://www.etenders.gov.za/home/Download/?blobName=f8e54a24-0a99-4221-860c-8f26cd506c32.pdf&downloadedFileName=Expression%20of%20Interest%20for%20Contractors.pdf
A9: 46163 | B9: 185 | C9: E2922GXMPKUS- | D9: 46160 | E9: 46174 | F9: 10:00 | G9: Request for Quotation | H9: Supply and Delivery of Spares (Boiler spares) for Replenishment at Kusile Power Station (Once-off) | I9: ETENDERS.GOV.ZA | J9: ESKOM | K9: Mpumalanga | L9: No | M9: Supplies: General | N9: Yes | O9: N/A | P9: Yes | Q9: MSTEAM | R9: https://www.etenders.gov.za/home/Download/?blobName=bc1c5767-4b41-4902-b7ed-6a93ee8cfcab.pdf&downloadedFileName=TES%20Boiler%20Spares%2025.03.2026.pdf
A10: 46163 | B10: 184 | C10: LPT/QUT 004/2025 | D10: 46160 | E10: 46178 | F10: 11:00 | G10: Request for Quotation | H10: FUMIGATION AND RODENT CONTROL SERVICES FOR LIMPOPO PROVINCIAL TREASURY DEPARTMENTAL BUILDINGS/FACILITIES | I10: ETENDERS.GOV.ZA | J10: Limpopo - Provincial Treasury | K10: Limpopo | L10: No | M10: Services: Building | N10: Yes | O10: 46170 | P10: Yes | Q10: 46 Hans van Rensburg Street, Polokwane Limpopo 0699 | R10: https://www.etenders.gov.za/home/Download/?blobName=cd49ef16-8d72-4481-a265-78272a3b88dc.pdf&downloadedFileName=LPT%20QUT%20004%202026%20FUMIGATION%20SERVICES.pdf
A11: 46163 | B11: 183 | C11: WTE-2608ES | D11: 46160 | E11: 46178 | F11: 11:00 | G11: Request for Quotation | H11: APPOINTMENT OF A PROFESSIONAL SERVICE PROVIDER TO CONDUCT OCCUPATIONAL HEALTH AND SAFETY(OHS) AUDITS FOR THE DEPARTMENT OF WATER AND SANITATION: EASTERN OPERATIONS | I11: ETENDERS.GOV.ZA | J11: Water and Sanitation | K11: KwaZulu-Natal | L11: No | M11: Human health activities | N11: No | O11: N/A | P11: No | Q11: N/A | R11: https://www.etenders.gov.za/home/Download/?blobName=f221b56e-d030-40c6-bf75-e69f391c06d2.pdf&downloadedFileName=General%20Conditions%20of%20Contract-%20Inclusion%20of%20par%2034%20CIBD.pdf
A12: 46163 | B12: 182 | C12: IHLM/187/2025-26/COMM | D12: 46160 | E12: 46169 | F12: 12:00 | G12: Request for Quotation | H12: PROCUREMENT OF TORCHES, PEPPER SPRAYS WITH POUCHES | I12: ETENDERS.GOV.ZA | J12: Ingquza Hill Local Municipality | K12: Eastern Cape | L12: No | M12: Supplies: General | N12: No | O12: N/A | P12: No | Q12: N/A | R12: https://www.etenders.gov.za/home/Download/?blobName=162fb755-f198-4e7f-94a8-67060b6f9513.pdf&downloadedFileName=BID%20DOCUMENT%20FOR%20PROCUREMENT%20OF%20TORCHES,%20PEPPER%20SPRAYS%20WITH%20POUCHES.pdf
A13: 46163 | B13: 181 | C13: ULM-INFR 015/26 | D13: 46160 | E13: 46178 | F13: 12:00 | G13: Request for Bid(Open-Tender) | H13: Completion of Ntlangwini Low Level Bridge ( Ward 18) | I13: ETENDERS.GOV.ZA | J13: Umzimkhulu Local Municipality | K13: KwaZulu-Natal | L13: No | M13: Construction | N13: Yes | O13: 46171 | P13: Yes | Q13: uMzimkhulu Municipality Makhosini Building Boardroom,247 Mzimkhulu Mlonyana Street, uMzimkhulu 3297. | R13: https://www.etenders.gov.za/home/Download/?blobName=203b6931-43bc-4491-862e-253edee2e4e5.pdf&downloadedFileName=18-05-2026%20TENDER%20ADVERT%20-COMPLETION%20OF%20NTLANGWINI%20LOW%20LEVEL%20BRIDGE%20(%20WARD%2018).pdf
A14: 46163 | B14: 180 | C14: bm28/25/26 | D14: 46160 | E14: 46191 | F14: 11:00 | G14: Request for Bid(Open-Tender) | H14: APPOINTMENT OF SERVICE PROVIDER TO SUPPLY, INSTALLATION AND MAINTENACE OF TELEPHONE SYSTEM FOR A PERIOD OF 36 MONTHS | I14: ETENDERS.GOV.ZA | J14: Blouberg Municipality | K14: Limpopo | L14: No | M14: Information and communication | N14: No | O14: N/A | P14: No | Q14: N/A | R14: https://www.etenders.gov.za/home/Download/?blobName=b2094674-6233-489e-a3b7-332f3b36fba3.pdf&downloadedFileName=Telephone%20tender%20advert05-18-2026-151330.pdf
A15: 46163 | B15: 179 | C15: SASSA:01-26-FAC-NW | D15: 46160 | E15: 46183 | F15: 11:00 | G15: Request for Proposal | H15: LEASING OF OFFICE ACCOMODATION FOR SASSA NORTH-WEST REGION FOR A PERIOD OF FIVE (05) YEARS IN MOGWASE CBD | I15: ETENDERS.GOV.ZA | J15: South African Social Security Agency | K15: North West | L15: No | M15: Accommodation | N15: No | O15: N/A | P15: No | Q15: N/A | R15: https://www.etenders.gov.za/home/Download/?blobName=f54073e2-f0f6-41ac-a1e8-f92d314404e5.pdf&downloadedFileName=SASSA%2001-26-FAC-NW%20Leasing%20of%20office%20accomodation%20for%20SASSA%20North-West%20Region%20for%20period%20of%20five(05)%20years%20in%20Mogwase%20CBD.pdf
A16: 46163 | B16: 178 | C16: ELM 25-26/05/03 | D16: 46160 | E16: 46188 | F16: 12:00 | G16: Request for Bid(Open-Tender) | H16: Provision of payroll and human resource management system with support and maintenance over a period of 60 months (5 years) for Emakhazeni Local Municipality | I16: ETENDERS.GOV.ZA | J16: EMAKHAZENI LOCAL MUNICIPALITY | K16: Mpumalanga | L16: No | M16: Services: Professional | N16: No | O16: N/A | P16: No | Q16: N/A | R16: https://www.etenders.gov.za/home/Download/?blobName=12471aa7-ecdc-4af2-8616-f4de6c55e8fb.pdf&downloadedFileName=Tender%20Data%20-%20HRM%20&%20Payroll.pdf
A17: 46163 | B17: 177 | C17: RFQJW112NS26 | D17: 46160 | E17: 46167 | F17: 16:00 | G17: Request for Quotation | H17: Supply, installation and Training of Wastewater Mathematical Modelling Software | I17: ETENDERS.GOV.ZA | J17: Johannesburg Water | K17: Gauteng | L17: No | M17: Other professional, scientific and technical activities | N17: No | O17: N/A | P17: No | Q17: N/A | R17: https://www.etenders.gov.za/home/Download/?blobName=74f6f1e7-37a7-470b-88e6-bcd8d7ce16d9.pdf&downloadedFileName=RFQJW112NS26-Supply,%20installation%20and%20Training%20of%20Wastewater%20Mathematical%20Modelling%20Software(18-25%20MAY.pdf
A18: 46163 | B18: 176 | C18: RFP/2021/001419 | D18: 46160 | E18: 46174 | F18: 11:00 | G18: Request for Quotation | H18: THE APPOINTMENT OF A SERVICE PROVIDER TO PROVIDE ENTERPRISE ARCHITECTURE SERVICES TO THE PSETA | I18: ETENDERS.GOV.ZA | J18: Public Service Sector Education and Training Authority | K18: Gauteng | L18: No | M18: Services: Professional | N18: Yes | O18: 46167 | P18: Yes | Q18: BRIEFING SESSION: MICROSOFT TEAMS | R18: https://www.etenders.gov.za/home/Download/?blobName=934c0a04-1f5c-4809-8486-429e03b0fd75.zip&downloadedFileName=RFP2021001419-ARCHITECTURE%20ENTERPRISE.zip
A19: 46163 | B19: 175 | C19: PR10115864 | D19: 46160 | E19: 46164 | F19: 14:00 | G19: Request for Quotation | H19: The Road Accident Fund (RAF) wishes to appoint a suitable service provider for the Design, Layout, Copy Editing, Proofreading, Interactive PDF Booklet and Printing of 2026 – 2027 Annual Performance Plan (APP). | I19: ETENDERS.GOV.ZA | J19: Road Accident Fund | K19: Gauteng | L19: No | M19: Services: Professional | N19: No | O19: N/A | P19: No | Q19: N/A | R19: https://www.etenders.gov.za/home/Download/?blobName=1b13318d-5497-4736-bc84-e088c2fcfd42.pdf&downloadedFileName=Annexure%20A%20-%20Security%20Measures.pdf
A20: 46163 | B20: 174 | C20: RFQ 144 | D20: 46160 | E20: 46168 | F20: 12:00 | G20: Request for Quotation | H20: Provision For Editing and Project management Training services | I20: ETENDERS.GOV.ZA | J20: Special Investigation Unit | K20: Gauteng | L20: No | M20: Education | N20: No | O20: N/A | P20: No | Q20: N/A | R20: https://www.etenders.gov.za/home/Download/?blobName=f42418e1-dc39-4aa2-a1f4-d7bd8b093194.pdf&downloadedFileName=RFQ%20144.pdf
A21: 46163 | B21: 173 | C21: SAST/RFQ/2026 -2027/360 | D21: 46160 | E21: 46171 | F21: 11:00 | G21: Request for Quotation | H21: THE APPOINTMENT OF A SERVICE PROVIDER FOR THE FUMIGATION SERVICES FOR THE PERIOD OF 36 MONTHS (Re-Issue) | I21: ETENDERS.GOV.ZA | J21: The South African State Theatre | K21: Gauteng | L21: No | M21: Other service activities | N21: No | O21: N/A | P21: No | Q21: N/A | R21: https://www.etenders.gov.za/home/Download/?blobName=af7ec8b4-a635-4f1f-b054-b6227a6fdfd8.pdf&downloadedFileName=SAST-RFQ-2026-360%20-%20Fumigation%20services%20for%2036%20months%20-%20Re-issue.pdf
A22: 46163 | B22: 172 | C22: NRWDI/ICT/2026-04 | D22: 46160 | E22: 46163 | F22: 17:00 | G22: Request for Quotation | H22: SUPPLY AND DELIVERY OF FIVE (5) LAPTOPS | I22: ETENDERS.GOV.ZA | J22: National Radioactive Waste Disposal Institute (NRWDI) | K22: North West | L22: No | M22: Supplies: Computer Equipment | N22: No | O22: N/A | P22: No | Q22: N/A | R22: https://www.etenders.gov.za/home/Download/?blobName=8c411dcd-7d36-4515-8b50-6acb7fa28e5c.pdf&downloadedFileName=NRWDI%20RFQ%20for%20Laptops.pdf
A23: 46163 | B23: 171 | C23: E1046GCDMPKUSR2C | D23: 46160 | E23: 46203 | F23: 11:00 | G23: Request for Bid(Open-Tender) | H23: Notification of cancellation_ E1046GCDMPKUSR2_ Wetland Offset at Kusile Power Station 60 Year ADF Project | I23: ETENDERS.GOV.ZA | J23: ESKOM | K23: Mpumalanga | L23: No | M23: Civil engineering | N23: No | O23: N/A | P23: No | Q23: N/A | R23: https://www.etenders.gov.za/home/Download/?blobName=cfc813e9-a278-4058-ae2c-61f53b9bd1e2.pdf&downloadedFileName=Tender%20Cancellation%20Letter%20Template%20-%20Wetland%20Offset.pdf
A24: 46163 | B24: 170 | C24: RFQ-PPECB/ GRABOUW-MAIN /04-26 | D24: 46160 | E24: 46178 | F24: 16:00 | G24: Request for Quotation | H24: THE PROVISION OF GENERAL MAINTENANCE SERVICES FOR THE GRABOUW OFFICE | I24: ETENDERS.GOV.ZA | J24: Perishable Products Export Control Board | K24: Western Cape | L24: No | M24: Services: General | N24: Yes | O24: 46170 | P24: Yes | Q24: 7 Bosbou Avenue, Grabouw, 7160 | R24: https://www.etenders.gov.za/home/Download/?blobName=74d3b7fb-505c-4cfa-9d15-97d1241ba161.pdf&downloadedFileName=RFQ%20Grabouw.pdf
A25: 46163 | B25: 169 | C25: FOSPHB-RFP-09-26/27 | D25: 46160 | E25: 46175 | F25: 12:00 | G25: Request for Proposal | H25: FOSPHB-RFP-09-26/27 REQUEST FOR PROPOSAL [RFP] ELECTRICAL SHUTDOWN WORK 2026 | I25: ETENDERS.GOV.ZA | J25: Industrial Development Corporation of South Africa Limited | K25: Limpopo | L25: No | M25: Supplies: General | N25: Yes | O25: 46163 | P25: Yes | Q25: Microsoft Teams | R25: https://www.etenders.gov.za/home/Download/?blobName=f4f34f2a-01e6-4807-9d1e-b44fb00243fc.zip&downloadedFileName=FOSPHB-RFP-09-2627-ELECTRICAL%20SHUTDOWN%20WORK%202026.zip
A26: 46163 | B26: 168 | C26: NLC2026-004 | D26: 46160 | E26: 46184 | F26: 11:00 | G26: Request for Proposal | H26: TERMS OF REFERENCE FOR THE APPOINTMENT OF SERVICE PROVIDER FOR THE PROVISION OF SPECIALISED TECHNICAL SYBRIN DEVELOPMENT RESOURCES FOR THE ENHANCEMENT OF THE THUTHUKA GRANTS MANAGEMENT SYSTEM FOR A PERIOD OF THREE YEARS. | I26: ETENDERS.GOV.ZA | J26: National Lotteries Commission | K26: National | L26: No | M26: Information service activities | N26: Yes | O26: 46171 | P26: Yes | Q26: Block D, Htfield Gardens, Corner Hilda and Arcadia Street. Hatfield | R26: https://www.etenders.gov.za/home/Download/?blobName=2697f098-25db-45ad-9f20-f9529cb2cfa9.xlsx&downloadedFileName=Annexure%20C_Sybrin_Pricing_Schedule_25.03.2026.xlsx
A27: 46163 | B27: 167 | C27: RFB 3238-2026 ERP NO:374011 | D27: 46160 | E27: 46188 | F27: 11:00 | G27: Request for Bid(Open-Tender) | H27: REQUEST FOR BID FOR THE PROCUREMENT OF A MANAGEMENT ADMINISTRATION SYSTEM (MAS) FOR THE FOUR NURSING COLLEGE CAMPUSES OF THE WESTERN CAPE COLLEGE OF NURSING, INCLUDING COLLEGE OF EMERGENCY CARE, WESTERN CAPE DEPARTMENT OF HEALTH & WELLNESS FOR A 5-YEAR PERIOD. COMPULSORY VIRTUAL SESSION WILL BE HELD ON 02 JUNE 2026 AT 11H00AM. | I27: ETENDERS.GOV.ZA | J27: State Information Technology Agency | K27: Western Cape | L27: No | M27: Information service activities | N27: Yes | O27: 46175 | P27: Yes | Q27: https://teams.microsoft.com/meet/378792528716857?p=IWlNcmRCYBQHR55m4n | R27: https://www.etenders.gov.za/home/Download/?blobName=3df52742-d738-421a-bbfa-9b0f85a8e006.pdf&downloadedFileName=Annexure%205a-Invitation%20Letter-RFB%203238-2026%2018052026.pdf
A28: 46163 | B28: 166 | C28: PR10116177 | D28: 46160 | E28: 46164 | F28: 11:00 | G28: Request for Quotation | H28: The Road Accident Fund (RAF) wishes to appoint a suitable service provider to provide Ambulance Services for the RAF on the Road Roadshow in Bethlehem on 13 June 2026. | I28: ETENDERS.GOV.ZA | J28: Road Accident Fund | K28: Free State | L28: No | M28: Services: General | N28: No | O28: N/A | P28: No | Q28: N/A | R28: https://www.etenders.gov.za/home/Download/?blobName=c1913a2b-db57-436e-957c-fad403f66573.pdf&downloadedFileName=Standard%20Bidding%20Document%20(SDB)%204.pdf
A29: 46163 | B29: 165 | C29: WTE-2607ES | D29: 46160 | E29: 46178 | F29: 11:00 | G29: Request for Quotation | H29: SUPPLY AND DELIVERY OF PLUMBING, MECHANICAL & ELECTRICAL TOOLS TO MIDMAR DAM NEAR HOWICK TOWN | I29: ETENDERS.GOV.ZA | J29: Water and Sanitation | K29: KwaZulu-Natal | L29: No | M29: Supplies: General | N29: No | O29: N/A | P29: No | Q29: N/A | R29: https://www.etenders.gov.za/home/Download/?blobName=a2bbd5df-eba8-43c0-9b83-f6a3c043ab11.pdf&downloadedFileName=guidelines%20for%20local%20content.pdf
A30: 46163 | B30: 164 | C30: DQP 16/2026 LG | D30: 46160 | E30: 46167 | F30: 11:00 | G30: Request for Quotation | H30: APPOINTMENT OF A SERVICE PROVIDER TO CONDUCT TRAINING FOR 60 OFFICIALS MS WORD 1 & 2 AND 60 OFFICIALS MS EXCEL 1 & 2 | I30: ETENDERS.GOV.ZA | J30: Kwazulu Natal - Cooperative Governance and Traditional Affairs | K30: KwaZulu-Natal | L30: No | M30: Services: Professional | N30: No | O30: N/A | P30: No | Q30: N/A | R30: https://www.etenders.gov.za/home/Download/?blobName=a7c09eda-5625-47aa-a1c1-83ada59be118.pdf&downloadedFileName=DQP%20162026%20LG%20%E2%80%93%20REQA60188.pdf
A31: 46163 | B31: 163 | C31: RFQJS36SN26 | D31: 46160 | E31: 46167 | F31: 16:00 | G31: Request for Quotation | H31: Repair steps at unit 3 bioreactors and supply cordless drill kit set | I31: ETENDERS.GOV.ZA | J31: Johannesburg Water | K31: Gauteng | L31: No | M31: Other personal service activities | N31: Yes | O31: 46163 | P31: Yes | Q31: Northern Works , off Winnie Mandela Drive school Road Diepsloot | R31: https://www.etenders.gov.za/home/Download/?blobName=01f3ae46-cf5e-4f7d-8a13-fb32474ae03c.pdf&downloadedFileName=RFQJW36SN26.pdf
A32: 46163 | B32: 162 | C32: ASA 04/05/2026 | D32: 46160 | E32: 46167 | F32: 12:00 | G32: Request for Quotation | H32: Appointment of a service provider to assist with purchasing and delivery of kitchen surplus | I32: ETENDERS.GOV.ZA | J32: Agrément South Africa | K32: National | L32: No | M32: Food and beverage service activities | N32: No | O32: N/A | P32: No | Q32: N/A | R32: https://www.etenders.gov.za/home/Download/?blobName=9f1d413d-051c-4650-91b1-f732f4019189.pdf&downloadedFileName=Terms%20of%20Reference%20-%20Purchasing%20of%20Grocery.pdf
A33: 46163 | B33: 161 | C33: SASSA:01-26-CS-LP | D33: 46160 | E33: 46181 | F33: 11:00 | G33: Request for Proposal | H33: Acquisition of an office accommodation for SASSA Limpopo Regional Office and Capricon District Office ( Combined Space) for a period of five (5) years. | I33: ETENDERS.GOV.ZA | J33: South African Social Security Agency | K33: Limpopo | L33: No | M33: Accommodation | N33: Yes | O33: 46167 | P33: No | Q33: VIRTUAL(MICROSOFT TEAMS) | R33: https://www.etenders.gov.za/home/Download/?blobName=e6ca7df1-0195-4c12-bc30-86da7d3426cc.pdf&downloadedFileName=SASSA-01-26-CS-LP.pdf
A34: 46163 | B34: 160 | C34: RFP-HO-04-2026 | D34: 46160 | E34: 46169 | F34: 11:00 | G34: Request for Proposal | H34: Appointment of Labour Relations Retainer for a period of 36 months (3 years) | I34: ETENDERS.GOV.ZA | J34: South African Human Rights Commission | K34: Gauteng | L34: No | M34: Legal and accounting activities | N34: Yes | O34: 46163 | P34: No | Q34: https://teams.microsoft.com/meet/329382618243468?p=X3C11r21xltocSMwf2 | R34: https://www.etenders.gov.za/home/Download/?blobName=4c222714-27be-4b64-8d24-09434f1d8c57.pdf&downloadedFileName=RFP-HO-04-2026-%20Labour%20Relation%20Service%20Retainer-001.pdf
A35: 46163 | B35: 159 | C35: DQP 20/2026 LG | D35: 46160 | E35: 46167 | F35: 11:00 | G35: Request for Quotation | H35: APPOINTMENT OF A SERVICE PROVIDER TO CONDUCT TRAINING FOR 68 OFFICIALS ON PROJECT MANAGEMENT | I35: ETENDERS.GOV.ZA | J35: Kwazulu Natal - Cooperative Governance and Traditional Affairs | K35: KwaZulu-Natal | L35: No | M35: Services: Professional | N35: No | O35: N/A | P35: No | Q35: N/A | R35: https://www.etenders.gov.za/home/Download/?blobName=78f9b89e-032f-47af-8fde-a159a6714d1a.pdf&downloadedFileName=DQP%20202026%20LG%20%E2%80%93%20REQA60192.pdf
A36: 46163 | B36: 158 | C36: ZNT 01-26-27 | D36: 46160 | E36: 46195 | F36: 11:00 | G36: Request for Bid(Open-Tender) | H36: Appointment of a service provider for the supply and delivery of stationery items on a two (2) year period contract (24 months). | I36: ETENDERS.GOV.ZA | J36: Kwazulu Natal - Public Works (Head Office) | K36: KwaZulu-Natal | L36: No | M36: Supplies: Stationery/Printing | N36: No | O36: N/A | P36: No | Q36: N/A | R36: https://www.etenders.gov.za/home/Download/?blobName=82bde937-63ac-4671-99b1-e77920f0de37.pdf&downloadedFileName=ZNT%2001-26-27%20advert.pdf
A37: 46163 | B37: 157 | C37: OLT2128185 | D37: 46160 | E37: 46168 | F37: 10:00 | G37: Request for Proposal | H37: Purchase, collect and Remove Scrapped and contaminated petrol and diesel from Komati Power Station at Eskom Mpumalanga | I37: ETENDERS.GOV.ZA | J37: ESKOM | K37: Mpumalanga | L37: No | M37: Disposals: General | N37: No | O37: N/A | P37: No | Q37: N/A | R37: https://www.etenders.gov.za/home/Download/?blobName=0eee4ba2-7634-490b-a7b7-6157c9605577.pdf&downloadedFileName=Eskom%20life-saving%20rules.pdf
A38: 46163 | B38: 156 | C38: ATNS/RFQ12/05/2026/27/ATA_Fans_Hardrives | D38: 46160 | E38: 46163 | F38: 11:00 | G38: Request for Quotation | H38: APPOINTMENT OF A SERVICE PROVIDER FOR THE SUPPLY AND DELIVERY OF HARDRIVES AND COOLING FANS AT THE ATNS AVIATION TRAINING ACADEMY | I38: ETENDERS.GOV.ZA | J38: Air Traffic and Navigation Services Company Limited | K38: Gauteng | L38: No | M38: Supplies: Computer Equipment | N38: No | O38: N/A | P38: No | Q38: N/A | R38: https://www.etenders.gov.za/home/Download/?blobName=277073aa-62b7-4fb0-b755-cf2742cec093.pdf&downloadedFileName=ATA%20-%20RFQ%20for%20Supply%20and%20Delivery%20of%20Colling%20Fans%20and%20Hardrives.pdf
A39: 46163 | B39: 155 | C39: GKM 48-25/26 | D39: 46160 | E39: 46175 | F39: 12:00 | G39: Request for Bid(Open-Tender) | H39: APPOINTMENT OF A SERVICE PROVIDER FOR THE SUPPLY & DELIVERY OF A RIDE ON ROAD MARKING MACHINE WITH BOOSTER & TO PROVIDE TRAINING ON THE HANDLE & USE OF THE MACHINE | I39: ETENDERS.GOV.ZA | J39: Greater Kokstad Local Municipality | K39: KwaZulu-Natal | L39: No | M39: Supplies: General | N39: No | O39: N/A | P39: No | Q39: N/A | R39: https://www.etenders.gov.za/home/Download/?blobName=f4b095fe-ffd4-4c56-a00a-dfceef02c00c.pdf&downloadedFileName=TOR%20RIDE%20ON%20ROAD%20MARKING%20MACHINE.pdf
A40: 46163 | B40: 154 | C40: INF012605RFQ11 | D40: 46160 | E40: 46167 | F40: 11:00 | G40: Request for Quotation | H40: Supply and Deliver of Bottles and Corks - Western Cape - Stellenbosch | I40: ETENDERS.GOV.ZA | J40: Agricultural Research Council | K40: Western Cape | L40: No | M40: Supplies: General | N40: No | O40: N/A | P40: No | Q40: N/A | R40: https://www.etenders.gov.za/home/Download/?blobName=dfe76ef5-0e9c-4d39-abfa-223fb6d652b9.pdf&downloadedFileName=SPECS%20WINE%20BOTTLES%20AND%20CORKS%20INF012506RFQ11.pdf
...

Sheet Final
A1: Source | B1: Number of New Tenders | C1: ICT Tenders | D1: RFQs
A2: Report Date | B2: (T) 20/05/2026
A3: eTenders (All) | B3: =COUNTA('Tender Data'!J:J)-1 -> 192 | C3: =COUNTIF('Tender Data'!M:M,"Information service activities")+COUNTIF('Tender Data'!M:M,"Information and communication") -> 12 | D3: =COUNTIF('Tender Data'!G:G,"Request for Quotation") -> 89
A4: Eskom | B4: =COUNTIF('Tender Data'!J:J,"ESKOM") -> 18 | C4: =COUNTIFS('Tender Data'!M:M,"Information service activities",'Tender Data'!J:J,"ESKOM")+COUNTIFS('Tender Data'!M:M,"Information and communication",'Tender Data'!J:J,"ESKOM") -> 0 | D4: =COUNTIFS('Tender Data'!J:J,"ESKOM",'Tender Data'!G:G,"Request for Quotation") -> 5
A5: SITA | B5: =COUNTIF('Tender Data'!J:J,"State Information Technology Agency") -> 1 | C5: =COUNTIFS('Tender Data'!M:M,"Information service activities",'Tender Data'!J:J,"State Information Technology Agency")+COUNTIFS('Tender Data'!M:M,"Information and communication",'Tender Data'!J:J,"State Information Technology Agency") -> 1 | D5: =COUNTIFS('Tender Data'!J:J,"State Information Technology Agency",'Tender Data'!G:G,"Request for Quotation") -> 0
A6: Transnet | B6: =COUNTIF('Tender Data'!J:J,"Transnet*") -> 4 | C6: =COUNTIFS('Tender Data'!M:M,"Information service activities",'Tender Data'!J:J,"Transnet*")+COUNTIFS('Tender Data'!M:M,"Information and communication",'Tender Data'!J:J,"Transnet*") -> 0 | D6: =COUNTIFS('Tender Data'!J:J,"Transnet*",'Tender Data'!G:G,"Request for Quotation") -> 1
A7: JPC | B7: =COUNTIF('Tender Data'!J:J,"*Joburg Property*") -> 0 | C7: =COUNTIFS('Tender Data'!M:M,"Information service activities",'Tender Data'!J:J,"*Joburg Property*")+COUNTIFS('Tender Data'!M:M,"Information and communication",'Tender Data'!J:J,"*Joburg Property*") -> 0 | D7: =COUNTIFS('Tender Data'!J:J,"*Joburg Property*",'Tender Data'!G:G,"Request for Quotation") -> 0
A8: Matatiele LM | B8: =COUNTIF('Tender Data'!J:J,"Matatiele Local Municipality") -> 0 | C8: =COUNTIFS('Tender Data'!M:M,"Information service activities",'Tender Data'!J:J,"Matatiele Local Municipality")+COUNTIFS('Tender Data'!M:M,"Information and communication",'Tender Data'!J:J,"Matatiele Local Municipality") -> 0 | D8: =COUNTIFS('Tender Data'!J:J,"Matatiele Local Municipality",'Tender Data'!G:G,"Request for Quotation") -> 0
A9: Ntabankulu LM | B9: =COUNTIF('Tender Data'!J:J,"Ntabankulu Local Municipality") -> 0 | C9: =COUNTIFS('Tender Data'!M:M,"Information service activities",'Tender Data'!J:J,"Ntabankulu Local Municipality")+COUNTIFS('Tender Data'!M:M,"Information and communication",'Tender Data'!J:J,"Ntabankulu Local Municipality") -> 0 | D9: =COUNTIFS('Tender Data'!J:J,"Ntabankulu Local Municipality",'Tender Data'!G:G,"Request for Quotation") -> 0
A10: Umzimvubu LM | B10: =COUNTIF('Tender Data'!J:J,"Umzimvubu Local Municipality") -> 0 | C10: =COUNTIFS('Tender Data'!M:M,"Information service activities",'Tender Data'!J:J,"Umzimvubu Local Municipality")+COUNTIFS('Tender Data'!M:M,"Information and communication",'Tender Data'!J:J,"Umzimvubu Local Municipality") -> 0 | D10: =COUNTIFS('Tender Data'!J:J,"Umzimvubu Local Municipality",'Tender Data'!G:G,"Request for Quotation") -> 0
A11: Winnie Mandela LM | B11: =COUNTIF('Tender Data'!J:J,"Winnie Madikizela*") -> 0 | C11: =COUNTIFS('Tender Data'!M:M,"Information service activities",'Tender Data'!J:J,"Winnie Madikizela*")+COUNTIFS('Tender Data'!M:M,"Information and communication",'Tender Data'!J:J,"Winnie Madikizela*") -> 0 | D11: =COUNTIFS('Tender Data'!J:J,"Winnie Madikizela*",'Tender Data'!G:G,"Request for Quotation") -> 0
A12: Mnquma LM | B12: =COUNTIF('Tender Data'!J:J,"Mnquma Local Municipality") -> 0 | C12: =COUNTIFS('Tender Data'!M:M,"Information service activities",'Tender Data'!J:J,"Mnquma Local Municipality")+COUNTIFS('Tender Data'!M:M,"Information and communication",'Tender Data'!J:J,"Mnquma Local Municipality") -> 0 | D12: =COUNTIFS('Tender Data'!J:J,"Mnquma Local Municipality",'Tender Data'!G:G,"Request for Quotation") -> 0
A13: Great Kei LM | B13: =COUNTIF('Tender Data'!J:J,"Great Kei Local Municipality") -> 0 | C13: =COUNTIFS('Tender Data'!M:M,"Information service activities",'Tender Data'!J:J,"Great Kei Local Municipality")+COUNTIFS('Tender Data'!M:M,"Information and communication",'Tender Data'!J:J,"Great Kei Local Municipality") -> 0 | D13: =COUNTIFS('Tender Data'!J:J,"Great Kei Local Municipality",'Tender Data'!G:G,"Request for Quotation") -> 0
A14: Amahlathi LM | B14: =COUNTIF('Tender Data'!J:J,"Amahlathi Local Municipality") -> 0 | C14: =COUNTIFS('Tender Data'!M:M,"Information service activities",'Tender Data'!J:J,"Amahlathi Local Municipality")+COUNTIFS('Tender Data'!M:M,"Information and communication",'Tender Data'!J:J,"Amahlathi Local Municipality") -> 0 | D14: =COUNTIFS('Tender Data'!J:J,"Amahlathi Local Municipality",'Tender Data'!G:G,"Request for Quotation") -> 0
A15: Raymond Mhlaba LM | B15: =COUNTIF('Tender Data'!J:J,"Raymond Mhlaba Local Municipality") -> 0 | C15: =COUNTIFS('Tender Data'!M:M,"Information service activities",'Tender Data'!J:J,"Raymond Mhlaba Local Municipality")+COUNTIFS('Tender Data'!M:M,"Information and communication",'Tender Data'!J:J,"Raymond Mhlaba Local Municipality") -> 0 | D15: =COUNTIFS('Tender Data'!J:J,"Raymond Mhlaba Local Municipality",'Tender Data'!G:G,"Request for Quotation") -> 0
A16: JOSHCO | B16: =COUNTIF('Tender Data'!J:J,"*Johannesburg Social Housing*") -> 0 | C16: =COUNTIFS('Tender Data'!M:M,"Information service activities",'Tender Data'!J:J,"*Johannesburg Social Housing*")+COUNTIFS('Tender Data'!M:M,"Information and communication",'Tender Data'!J:J,"*Johannesburg Social Housing*") -> 0 | D16: =COUNTIFS('Tender Data'!J:J,"*Johannesburg Social Housing*",'Tender Data'!G:G,"Request for Quotation") -> 0
A17: GPL | B17: =COUNTIF('Tender Data'!J:J,"Gauteng Provincial Legislature") -> 0 | C17: =COUNTIFS('Tender Data'!M:M,"Information service activities",'Tender Data'!J:J,"Gauteng Provincial Legislature")+COUNTIFS('Tender Data'!M:M,"Information and communication",'Tender Data'!J:J,"Gauteng Provincial Legislature") -> 0 | D17: =COUNTIFS('Tender Data'!J:J,"Gauteng Provincial Legislature",'Tender Data'!G:G,"Request for Quotation") -> 0
A18: RAF | B18: =COUNTIF('Tender Data'!J:J,"Road Accident Fund") -> 3 | C18: =COUNTIFS('Tender Data'!M:M,"Information service activities",'Tender Data'!J:J,"Road Accident Fund")+COUNTIFS('Tender Data'!M:M,"Information and communication",'Tender Data'!J:J,"Road Accident Fund") -> 1 | D18: =COUNTIFS('Tender Data'!J:J,"Road Accident Fund",'Tender Data'!G:G,"Request for Quotation") -> 2
A19: MM Trading Company | B19: =COUNTIF('Tender Data'!J:J,"*Metropolitan Trading*") -> 0 | C19: =COUNTIFS('Tender Data'!M:M,"Information service activities",'Tender Data'!J:J,"*Metropolitan Trading*")+COUNTIFS('Tender Data'!M:M,"Information and communication",'Tender Data'!J:J,"*Metropolitan Trading*") -> 0 | D19: =COUNTIFS('Tender Data'!J:J,"*Metropolitan Trading*",'Tender Data'!G:G,"Request for Quotation") -> 0
A20: Nelson Mandela Bay MM | B20: =COUNTIF('Tender Data'!J:J,"*Nelson Mandela Bay*") -> 0 | C20: =COUNTIFS('Tender Data'!M:M,"Information service activities",'Tender Data'!J:J,"*Nelson Mandela Bay*")+COUNTIFS('Tender Data'!M:M,"Information and communication",'Tender Data'!J:J,"*Nelson Mandela Bay*") -> 0 | D20: =COUNTIFS('Tender Data'!J:J,"*Nelson Mandela Bay*",'Tender Data'!G:G,"Request for Quotation") -> 0
A21: Buffalo City MM | B21: =COUNTIF('Tender Data'!J:J,"*Buffalo City*") -> 0 | C21: =COUNTIFS('Tender Data'!M:M,"Information service activities",'Tender Data'!J:J,"*Buffalo City*")+COUNTIFS('Tender Data'!M:M,"Information and communication",'Tender Data'!J:J,"*Buffalo City*") -> 0 | D21: =COUNTIFS('Tender Data'!J:J,"*Buffalo City*",'Tender Data'!G:G,"Request for Quotation") -> 0
A22: EC DPW | B22: =COUNTIF('Tender Data'!J:J,"*Eastern Cape*Public Works*") -> 2 | C22: =COUNTIFS('Tender Data'!M:M,"Information service activities",'Tender Data'!J:J,"*Eastern Cape*Public Works*")+COUNTIFS('Tender Data'!M:M,"Information and communication",'Tender Data'!J:J,"*Eastern Cape*Public Works*") -> 0 | D22: =COUNTIFS('Tender Data'!J:J,"*Eastern Cape*Public Works*",'Tender Data'!G:G,"Request for Quotation") -> 1
A23: DEL | B23: =COUNTIF('Tender Data'!J:J,"*Labour*") -> 0 | C23: =COUNTIFS('Tender Data'!M:M,"Information service activities",'Tender Data'!J:J,"*Labour*")+COUNTIFS('Tender Data'!M:M,"Information and communication",'Tender Data'!J:J,"*Labour*") -> 0 | D23: =COUNTIFS('Tender Data'!J:J,"*Labour*",'Tender Data'!G:G,"Request for Quotation") -> 0
A24: SIU | B24: =COUNTIF('Tender Data'!J:J,"Special Investigations Unit*") -> 0 | C24: =COUNTIFS('Tender Data'!M:M,"Information service activities",'Tender Data'!J:J,"Special Investigations Unit*")+COUNTIFS('Tender Data'!M:M,"Information and communication",'Tender Data'!J:J,"Special Investigations Unit*") -> 0 | D24: =COUNTIFS('Tender Data'!J:J,"Special Investigations Unit*",'Tender Data'!G:G,"Request for Quotation") -> 0
A25: GDoH | B25: =COUNTIF('Tender Data'!J:J,"*Gauteng*Health*") -> 0 | C25: =COUNTIFS('Tender Data'!M:M,"Information service activities",'Tender Data'!J:J,"*Gauteng*Health*")+COUNTIFS('Tender Data'!M:M,"Information and communication",'Tender Data'!J:J,"*Gauteng*Health*") -> 0 | D25: =COUNTIFS('Tender Data'!J:J,"*Gauteng*Health*",'Tender Data'!G:G,"Request for Quotation") -> 0
A26: DIRCO | B26: =COUNTIF('Tender Data'!J:J,"*International Relation*") -> 0 | C26: =COUNTIFS('Tender Data'!M:M,"Information service activities",'Tender Data'!J:J,"*International Relation*")+COUNTIFS('Tender Data'!M:M,"Information and communication",'Tender Data'!J:J,"*International Relation*") -> 0 | D26: =COUNTIFS('Tender Data'!J:J,"*International Relation*",'Tender Data'!G:G,"Request for Quotation") -> 0
A27: CP JHB | B27: =COUNTIF('Tender Data'!J:J,"*Joburg Property*") -> 0 | C27: =COUNTIFS('Tender Data'!M:M,"Information service activities",'Tender Data'!J:J,"*Joburg Property*")+COUNTIFS('Tender Data'!M:M,"Information and communication",'Tender Data'!J:J,"*Joburg Property*") -> 0 | D27: =COUNTIFS('Tender Data'!J:J,"*Joburg Property*",'Tender Data'!G:G,"Request for Quotation") -> 0
A28: W JHB | B28: =COUNTIF('Tender Data'!J:J,"*Johannesburg Water*") -> 11 | C28: =COUNTIFS('Tender Data'!M:M,"Information service activities",'Tender Data'!J:J,"*Johannesburg Water*")+COUNTIFS('Tender Data'!M:M,"Information and communication",'Tender Data'!J:J,"*Johannesburg Water*") -> 0 | D28: =COUNTIFS('Tender Data'!J:J,"*Johannesburg Water*",'Tender Data'!G:G,"Request for Quotation") -> 11
B29: =SUM(B4:B28) -> 39 | C29: =SUM(C4:C28) -> 2 | D29: =SUM(D4:D28) -> 20
