Workbook

Sheet Tender Data
A1: REPORT_DATE | B1: RECORD_ID | C1: TENDER_ID | D1: PUBLICATION_DATE | E1: CLOSING_DATE | F1: CLOSING_TIME | G1: TENDER_TYPE | H1: TENDER_DESCRIPTION | I1: TENDER_SOURCE | J1: DEPARTMENT | K1: PROVINCE | L1: ESUBMISSION | M1: CATEGORY | N1: IS_THERE_A_BRIEFING_SESSION | O1: COMPULSORY_BRIEFING | P1: BRIEFING_SESSION_VENUE | Q1: LINK | R1: SOE | S1: COST_OF_SALES_ESTIMATE | T1: CAPABILITY_AVAILABLE | U1: CAPABILITY_GROUP | V1: REQUIREMENTS
A2: 46191 | B2: 502 | C2: CO 26/12 O | D2: 46191 | E2: 46230 | F2: 12:00 | G2: Request for Bid(Open-Tender) | H2: Provision of Grounds and Gardening Services at Majuba TVET College for a period of 5 Years | I2: ETENDERS.GOV.ZA | J2: Majuba Tvet college | K2: KwaZulu-Natal | L2: No | M2: Other service activities | N2: Yes | O2: Yes | P2: Newcastle Training Centre Hall, 2 HJ Van Eck Avenue, Newcastle | Q2: https://www.etenders.gov.za/home/Download/?blobName=1debbfd3-bfd5-48cc-9819-dab8ebf24933.pdf&downloadedFileName=Advert%20for%20PROVISION%20OF%20GROUND%20AND%20GARDENING%20SERVICES%20AT%20MAJUBA%20TVET%20COLLEGE%20SITES%20FOR%20THE%20PERIOD%20OF%20(05)%20YEARS.pdf
A3: 46191 | B3: 501 | C3: IT 26/03 C | D3: 46191 | E3: 46230 | F3: 12:00 | G3: Request for Bid(Open-Tender) | H3: Provision of Endpoint Protection and XDR Security Solution at Majuba TVET College for the period of five (05) Years | I3: ETENDERS.GOV.ZA | J3: Majuba Tvet college | K3: KwaZulu-Natal | L3: No | M3: Information and communication | N3: Yes | O3: Yes | P3: Virtual meeting - the link will be shared with service providers that requested for the document | Q3: https://www.etenders.gov.za/home/Download/?blobName=3e0a07c5-0aab-491e-8cd4-3b631e78b5b1.pdf&downloadedFileName=Advert%20for%20Provision%20of%20internet%20services%20-%20End%20Point-%203%20Tier.pdf
A4: 46191 | B4: 500 | C4: GMT061/25-26 | D4: 46191 | E4: 46230 | F4: 12:00 | G4: Request for Bid(Open-Tender) | H4: Appointment of a Panel of Contractors to attend to Plumbing Related Services for Municipal Buildings and Facilities, Informal Settlement Areas and Indigent Households, as and when required, for a period of three (3) years from date of appointment until 30 June 2029 | I4: ETENDERS.GOV.ZA | J4: George Municipality | K4: Western Cape | L4: No | M4: Other service activities | N4: Yes | O4: Yes | P4: Conference Hall at George Municipality’s Civic Centre, York Street, George | Q4: https://www.etenders.gov.za/home/Download/?blobName=822effce-63d3-4ef3-b75c-03cdcac572ce.pdf&downloadedFileName=GMT061%20of%2025-26%20Tender%20document_18%20June%202026_%20Final.pdf
A5: 46191 | B5: 499 | C5: NKO10/2026 | D5: 46191 | E5: 46234 | F5: 12:00 | G5: Request for Bid(Open-Tender) | H5: APPOINTMENT OF A SUITABLE SERVICE PROVIDER FOR SUPPLY AND DELIVERY OF PROTECTIVE CLOTHING AND RELATED ITEMS FOR NKOMAZI LOCAL MUNICIPALITY FOR A PERIOD OF THREE YEARS (36 MONTHS) | I5: ETENDERS.GOV.ZA | J5: Nkomazi Local Municipality | K5: Mpumalanga | L5: No | M5: Supplies: Clothing/Textiles/Footwear | N5: Yes | O5: Yes | P5: Municipal Town Hall (Kobwa), Fish Eagle, Malalane | Q5: https://www.etenders.gov.za/home/Download/?blobName=f2432ad0-77b3-4217-aace-6ab28d55ed7a.pdf&downloadedFileName=NKO%2010%202026.pdf
A6: 46191 | B6: 498 | C6: IT 26/03 O | D6: 46191 | E6: 46226 | F6: 12:00 | G6: Request for Bid(Open-Tender) | H6: Provision of Internet Services at Majuba TVET College for the period of five(05) Years | I6: ETENDERS.GOV.ZA | J6: Majuba Tvet college | K6: KwaZulu-Natal | L6: No | M6: Information and communication | N6: Yes | O6: Yes | P6: 83 Allen Street, Newcastle | Q6: https://www.etenders.gov.za/home/Download/?blobName=aa42ef56-627e-43ee-8472-b8b52e5ca98b.pdf&downloadedFileName=Advert%20for%20Provision%20of%20internet%20services%20-%20End%20Point-%203%20Tier.pdf
A7: 46191 | B7: 497 | C7: IT 26/02 O | D7: 46191 | E7: 46226 | F7: 12:00 | G7: Request for Bid(Open-Tender) | H7: Provision of 3 Tier Virtual Environment at Majuba TVET College for the Period of (05) Five Years | I7: ETENDERS.GOV.ZA | J7: Majuba Tvet college | K7: KwaZulu-Natal | L7: No | M7: Information and communication | N7: Yes | O7: Yes | P7: 83 Allen Street, Newcastle | Q7: https://www.etenders.gov.za/home/Download/?blobName=ab8110d3-d32a-4e46-9514-4dade2be3b29.pdf&downloadedFileName=Advert%20for%20Provision%20of%20internet%20services%20-%20End%20Point-%203%20Tier.pdf
A8: 46191 | B8: 496 | C8: MDM 2025/26 -54 | D8: 46191 | E8: 46225 | F8: 12:00 | G8: Request for Bid(Open-Tender) | H8: Giyani Water Reticulation Phase 2A(Contract 014)-Mushiyani Water Reticulation | I8: ETENDERS.GOV.ZA | J8: Mopani District Municipality | K8: Limpopo | L8: No | M8: Civil engineering | N8: No | O8: No | P8: N/A | Q8: https://www.etenders.gov.za/home/Download/?blobName=3de493a7-77b0-4082-93f7-5392f24917ed.pdf&downloadedFileName=Giyani%20Water%20Reticulation%20to%20Villages%20Phase%202A%20-%20Final%20advert%20.pdf
A9: 46191 | B9: 495 | C9: MDM 2025/26 -55 | D9: 46191 | E9: 46225 | F9: 12:00 | G9: Request for Bid(Open-Tender) | H9: Giyani Water Reticulation Phase 2A(Contract 015)-Nsavulani Water Reticulation | I9: ETENDERS.GOV.ZA | J9: Mopani District Municipality | K9: Limpopo | L9: No | M9: Civil engineering | N9: No | O9: No | P9: N/A | Q9: https://www.etenders.gov.za/home/Download/?blobName=ff75eedc-33dd-4422-ad80-c8b5c3edd20d.pdf&downloadedFileName=Giyani%20Water%20Reticulation%20to%20Villages%20Phase%202A%20-%20Final%20advert%20.pdf
A10: 46191 | B10: 494 | C10: MDM 2025/26 -56 | D10: 46191 | E10: 46225 | F10: 12:00 | G10: Request for Bid(Open-Tender) | H10: Giyani Water Reticulation Phase 2A(Contract 016)-Nwadzekudzeku Water Reticulation | I10: ETENDERS.GOV.ZA | J10: Mopani District Municipality | K10: Limpopo | L10: No | M10: Civil engineering | N10: No | O10: No | P10: N/A | Q10: https://www.etenders.gov.za/home/Download/?blobName=6c20d68c-60b4-4bd6-bec6-d223d4334480.pdf&downloadedFileName=Giyani%20Water%20Reticulation%20to%20Villages%20Phase%202A%20-%20Final%20advert%20.pdf
A11: 46191 | B11: 493 | C11: MDM 2025/26 -57 | D11: 46191 | E11: 46225 | F11: 12:00 | G11: Request for Bid(Open-Tender) | H11: Giyani Water Reticulation Phase 2A(Contract 017)-Phlaubeni Water Reticulation | I11: ETENDERS.GOV.ZA | J11: Mopani District Municipality | K11: Limpopo | L11: No | M11: Civil engineering | N11: No | O11: No | P11: N/A | Q11: https://www.etenders.gov.za/home/Download/?blobName=e0fd5d6a-ebc0-4d41-8d0b-e7da53144af0.pdf&downloadedFileName=Giyani%20Water%20Reticulation%20to%20Villages%20Phase%202A%20-%20Final%20advert%20.pdf
A12: 46191 | B12: 492 | C12: MDM 2025/26 -58 | D12: 46191 | E12: 46225 | F12: 12:00 | G12: Request for Bid(Open-Tender) | H12: Giyani Water Reticulation Phase 2A(Contract 018)-Vuhehli Water Reticulation Contract B | I12: ETENDERS.GOV.ZA | J12: Mopani District Municipality | K12: Limpopo | L12: No | M12: Civil engineering | N12: No | O12: No | P12: N/A | Q12: https://www.etenders.gov.za/home/Download/?blobName=0d05656e-3662-4857-adb5-1edf132c6906.pdf&downloadedFileName=Giyani%20Water%20Reticulation%20to%20Villages%20Phase%202A%20-%20Final%20advert%20.pdf
A13: 46191 | B13: 491 | C13: MDM 2025/26 -59 | D13: 46191 | E13: 46225 | F13: 12:00 | G13: Request for Bid(Open-Tender) | H13: Giyani Water Reticulation Phase 2A(Contract 019)-Xikhumba Water Reticulation Contract A | I13: ETENDERS.GOV.ZA | J13: Mopani District Municipality | K13: Limpopo | L13: No | M13: Civil engineering | N13: No | O13: No | P13: N/A | Q13: https://www.etenders.gov.za/home/Download/?blobName=6259c7a5-5913-45da-ac0a-0c6715b34390.pdf&downloadedFileName=Giyani%20Water%20Reticulation%20to%20Villages%20Phase%202A%20-%20Final%20advert%20.pdf
... A337: 46194 | B337: 167 | C337: Table 01 | D337: 46194 | E337: 46198 | F337: 10:00 | G337: Request for Quotation | H337: Supply and delivery of Boardroom table | I337: ETENDERS.GOV.ZA | J337: South African Nuclear Energy Corporation Limited | K337: North West | L337: No | M337: Manufacture of furniture | N337: No | O337: No | P337: N/A | Q337: https://www.etenders.gov.za/home/Download/?blobName=f329ec1e-7fd4-4245-af1d-3b7843d6cfaf.docx&downloadedFileName=RFQ%20number%20Tables%2001.docx
A338: 46196 | B338: 166 | C338: BCM5-26/27-0013 | D338: 46196 | E338: 46205 | F338: 11:00 | G338: Request for Quotation | H338: QUOTATION FOR THE APPOINTMENT OF A SUITABLE SERVICE PROVIDER TO RENDER TRAINING SERVICES FOR MASTERING ENGINEERING AND CONSTRUCTION CONTRACTS FOR EIGHT (08) OFFICIALS AS PER SPECIFICATION TO THE EASTERN CAPE DEPARTMENT OF PUBLIC WORKS & INFRASTRUCTURE | I338: ECDPW.GOV.ZA | J338: Eastern Cape Department of Public Works and Infrastructure | K338: Eastern Cape | Q338: https://www.ecdpw.gov.za/wp-content/tender-uploads/bcm5-2627-0013.pdf
A339: 46196 | B339: 165 | C339: SCMU5-26/27-0035 | D339: 46195 | E339: 46210 | F339: 11:00 | G339: Request for Bid | H339: APPOINTMENT OF SERVICE PROVIDER FOR THE PROVISION OF ADEQUATE OFFICE ACCOMMODATION WITHIN MTHATHA CENTRAL BUSINESS DISTRICT - DEPARTMENT OF AGRICULTURE | I339: ECDPW.GOV.ZA | J339: Eastern Cape Department of Public Works and Infrastructure | K339: Eastern Cape | Q339: https://www.ecdpw.gov.za/wp-content/tender-uploads/department-of-agriculture--mthatha-cbd--final-0035.pdf
A340: 46196 | B340: 164 | C340: SCMU5-26/27-0034 | D340: 46195 | E340: 46210 | F340: 11:00 | G340: Request for Bid | H340: APPOINTMENT OF SERVICE PROVIDER FOR THE PROVISION OF ADEQUATE OFFICE ACCOMMODATION WITHIN MTHATHA CENTRAL BUSINESS DISTRICT - DEPARTMENT OF SOCIAL DEVELOPMENT: DISTRICT OFFICE | I340: ECDPW.GOV.ZA | J340: Eastern Cape Department of Public Works and Infrastructure | K340: Eastern Cape | Q340: https://www.ecdpw.gov.za/wp-content/tender-uploads/department-of-social-development-district-office--mthatha-cbd--final-0034.pdf
A341: 46196 | B341: 163 | C341: SCMU5-26/27-0029 | D341: 46195 | E341: 46224 | G341: Request for Bid | H341: TAFALOFEFE HOSPITAL: WATER AND WASTEWATER TREATMENT WORKS | I341: ECDPW.GOV.ZA | J341: Eastern Cape Department of Public Works and Infrastructure | K341: Eastern Cape | Q341: https://www.ecdpw.gov.za/wp-content/tender-uploads/scmu5-2627-0029_-tafalofefe-hospital--water-and-wastewater-treatment-works-.pdf
A342: 46196 | B342: 162 | C342: SCMU5-26/27-0033 | D342: 46195 | E342: 46210 | F342: 11:00 | G342: Request for Bid | H342: APPOINTMENT OF SERVICE PROVIDER FOR THE PROVISION OF ADEQUATE OFFICE ACCOMMODATION WITHIN MTHATHA CENTRAL BUSINESS DISTRICT - DEPARTMENT OF TRANSPORT | I342: ECDPW.GOV.ZA | J342: Eastern Cape Department of Public Works and Infrastructure | K342: Eastern Cape | Q342: https://www.ecdpw.gov.za/wp-content/tender-uploads/department-of-transport--mthatha-cbd--final-0033.pdf
A343: 46196 | B343: 161 | C343: SCMU5-26/27-0032 | D343: 46195 | E343: 46210 | F343: 11:00 | G343: Request for Bid | H343: APPOINTMENT OF SERVICE PROVIDER FOR THE PROVISION OF ADEQUATE OFFICE ACCOMMODATION WITHIN MTHATHA CENTRAL BUSINESS DISTRICT - DEPARTMENT OF SOCIAL DEVELOPMENT: LOCAL AREA OFFICE | I343: ECDPW.GOV.ZA | J343: Eastern Cape Department of Public Works and Infrastructure | K343: Eastern Cape | Q343: https://www.ecdpw.gov.za/wp-content/tender-uploads/department-of-social-development-local-area-office--mthatha-cbd--final-0032.pdf
A344: 46196 | B344: 160 | C344: SCMU5-26/27-0009 | D344: 46195 | G344: Request for Bid | H344: ERRATUM: TERM CONTRACT FOR MANAGEMENT AND ADMINISTERING PAYMENT OF MONTHLYSTIPEND FOR EPWP PARTICIPANTS FOR A PERIOD OF 3 YEARS. | I344: ECDPW.GOV.ZA | J344: Eastern Cape Department of Public Works and Infrastructure | K344: Eastern Cape | Q344: https://www.ecdpw.gov.za/wp-content/tender-uploads/erratum-scmu5-26-27-0009.pdf
A345: 46196 | B345: 159 | C345: SCMU5-26/27-0002 | D345: 46195 | E345: 46238 | F345: 14:00 | G345: Request for Bid | H345: EXPRESSION OF INTEREST FOR A PANEL OF TRAINING PROVIDERS FOR EPWP PROGRAMMES FOR A PERIOD OF THREE (3) YEARS. | I345: ECDPW.GOV.ZA | J345: Eastern Cape Department of Public Works and Infrastructure | K345: Eastern Cape | Q345: https://www.ecdpw.gov.za/wp-content/tender-uploads/0002-9.pdf
A346: 46196 | B346: 158 | C346: SCMU5-26/27-0022 | D346: 46195 | E346: 46224 | F346: 11:00 | G346: Request for Bid | H346: BID FOR THE APPOINTMENT OF SERVICE PROVIDER FOR THE RENEWAL OF SUPPORT AND MAINTENANCE FOR DISASTER RECOVERY AND MANAGED BACKUP SERVICES INCLUDING LICENSES FOR A PERIOD OF 24 MONTHS AS PER SPECIFICATION | I346: ECDPW.GOV.ZA | J346: Eastern Cape Department of Public Works and Infrastructure | K346: Eastern Cape | Q346: https://www.ecdpw.gov.za/wp-content/tender-uploads/scmu5-26-27-0022.pdf
A347: 46196 | B347: 157 | C347: BCM5-26/27-0012 | D347: 46192 | E347: 46196 | F347: 11:00 | G347: Request for Quotation | H347: QUOTATION FOR SUPPLY, DELIVERY AND DECANTING OF DIESEL AT AMALINDA OFFICES AS PER SPECIFICATION FROM DEPARTMENT OF PUBLIC WORKS AND INFRASTRUCTURE | I347: ECDPW.GOV.ZA | J347: Eastern Cape Department of Public Works and Infrastructure | K347: Eastern Cape | Q347: https://www.ecdpw.gov.za/wp-content/tender-uploads/bcm5-26-27-0012-quotation-for-supply-delivery-and-decanting-of-diesel-at---amalinda-offices-as-per-specification-from-department-of-public-works-and-infrastructure-.pdf
A348: 46196 | B348: 156 | C348: ALF5-26/27-0004 | D348: 46192 | E348: 46216 | F348: 11:00 | G348: Request for Bid | H348: TWO YEAR TERM CONTRACT FOR SUPPLY, SERVICING, REPAIRS AND MAINTENANCE OF GENERAL BUILDING FOR ALFRED NZO DISTRICT | I348: ECDPW.GOV.ZA | J348: Eastern Cape Department of Public Works and Infrastructure | K348: Eastern Cape | Q348: https://www.ecdpw.gov.za/wp-content/tender-uploads/alf5-26-27-0004-term-contract-gaeneral-building.pdf
A349: 46196 | B349: 155 | C349: ALF5-26/27-0003 | D349: 46192 | E349: 46213 | F349: 11:00 | G349: Request for Bid | H349: TWO YEAR TERM CONTRACT FOR SUPPLY, SERVICING, REPAIRS AND MAINTENANCE OF PLUMBING AND DRAINAGE EQUIPMENT IN ALFRED NZO DISTRICT | I349: ECDPW.GOV.ZA | J349: Eastern Cape Department of Public Works and Infrastructure | K349: Eastern Cape | Q349: https://www.ecdpw.gov.za/wp-content/tender-uploads/alf5-26-27-0003-term-contract-plumbing.pdf
A350: 46196 | B350: 154 | C350: ALF5-26/27-0002 | D350: 46192 | E350: 46213 | F350: 11:00 | G350: Request for Bid | H350: TWO YEAR TERM CONTRACT FOR SUPPLY, SERVICING, REPAIRS AND MAINTENANCE OF ELECTRICAL EQUIPMENT FOR ALFRED NZO DISTRICT | I350: ECDPW.GOV.ZA | J350: Eastern Cape Department of Public Works and Infrastructure | K350: Eastern Cape | Q350: https://www.ecdpw.gov.za/wp-content/tender-uploads/alf5-26-27-0002-term-contract-electical.pdf
A351: 46194 | B351: 153 | G351: Request for Bid | H351: Training on People 300 Skills Development and Emplyment Equity for 5 Employees | I351: NTABANKULU.GOV.ZA | J351: Ntabankulu Local Municipality | K351: Eastern Cape | Q351: https://www.ntabankulu.gov.za/2026/06/19/training-on-people-300-skills-development-and-emplyment-equity-for-5-employees/
A352: 46194 | B352: 152 | G352: Request for Bid | H352: Bid Invitation for Construction of Tsweleni AR and Gxwaleni Concrete Slab | I352: NTABANKULU.GOV.ZA | J352: Ntabankulu Local Municipality | K352: Eastern Cape | Q352: https://www.ntabankulu.gov.za/2026/06/19/bid-invitation-for-construction-of-tsweleni-ar-and-gxwaleni-concrete-slab/
A353: 46194 | B353: 151 | G353: Request for Bid | H353: CLOSING REGISTER FOR SUPPLY AND DELIVERY OF DIESEL | I353: NTABANKULU.GOV.ZA | J353: Ntabankulu Local Municipality | K353: Eastern Cape | Q353: https://www.ntabankulu.gov.za/2026/06/17/closing-register-for-supply-and-delivery-of-diesel/
A354: 46194 | B354: 150 | G354: Request for Bid | H354: CLOSING REGISTER FOR PROVISION OF SECURITY SERVICES | I354: NTABANKULU.GOV.ZA | J354: Ntabankulu Local Municipality | K354: Eastern Cape | Q354: https://www.ntabankulu.gov.za/2026/06/17/closing-register-for-provision-of-security-services/
A355: 46194 | B355: 149 | G355: Request for Bid | H355: TENDER DOCUMENTFOR 3 YEAR FRAMEWORK CONTRACT OF 05 ROAD MAINTENANCE CONTRACTORS | I355: NTABANKULU.GOV.ZA | J355: Ntabankulu Local Municipality | K355: Eastern Cape | Q355: https://www.ntabankulu.gov.za/2026/06/10/tender-documentfor-3-year-framework-contract-of-05-road-maintenance-contractors/
A356: 46194 | B356: 148 | G356: Request for Bid | H356: Closing Register for Construction of Fenced Mathole Pre-School with Ablution Facilities | I356: NTABANKULU.GOV.ZA | J356: Ntabankulu Local Municipality | K356: Eastern Cape | Q356: https://www.ntabankulu.gov.za/2026/06/03/closing-register-for-construction-of-fenced-mathole-pre-school-with-ablution-facilities/
A357: 46194 | B357: 147 | G357: Request for Bid | H357: Bid Invitation for Electrification and Maintenance Contractors | I357: NTABANKULU.GOV.ZA | J357: Ntabankulu Local Municipality | K357: Eastern Cape | Q357: https://www.ntabankulu.gov.za/2026/05/29/bid-invitation-for-electrification-and-maintenance-contractors/
A358: 46194 | B358: 146 | G358: Request for Bid | H358: Supply and Delivery of Kid’s Learning Gadgets | I358: NTABANKULU.GOV.ZA | J358: Ntabankulu Local Municipality | K358: Eastern Cape | Q358: https://www.ntabankulu.gov.za/2026/05/29/supply-and-delivery-of-kids-learning-gadgets-2/
A359: 46194 | B359: 145 | G359: Request for Bid | H359: Closing Register for Construction of Rwantsana Community Hall | I359: NTABANKULU.GOV.ZA | J359: Ntabankulu Local Municipality | K359: Eastern Cape | Q359: https://www.ntabankulu.gov.za/2026/05/26/closing-register-for-construction-of-rwantsana-community-hall/
A360: 46194 | B360: 144 | G360: Request for Bid | H360: Supply and Delivery of Diesel for 12 Months | I360: NTABANKULU.GOV.ZA | J360: Ntabankulu Local Municipality | K360: Eastern Cape | Q360: https://www.ntabankulu.gov.za/2026/05/21/supply-and-delivery-of-diesel-for-12-months/
A361: 46194 | B361: 143 | G361: Request for Bid | H361: WEBSITE HOSTING AND MAINTENANCE SERVICES FOR UMZIMVUBU LOCAL MUNICIPALITY FOR A PERIOD OF 3 YEARS (1) | I361: UMZIMVUBU.GOV.ZA | J361: Umzimvubu Local Municipality | K361: Eastern Cape | Q361: https://www.umzimvubu.gov.za/wp-content/uploads/2025/02/WEBSITE-HOSTING-AND-MAINTENANCE-SERVICES-FOR-UMZIMVUBU-LOCAL-MUNICIPALITY-FOR-A-PERIOD-OF-3-YEARS-1.pdf
A362: 46194 | B362: 142 | G362: Request for Bid | H362: Umndini Tender Document 1 | I362: UMZIMVUBU.GOV.ZA | J362: Umzimvubu Local Municipality | K362: Eastern Cape | Q362: https://www.umzimvubu.gov.za/wp-content/uploads/2025/02/Umndini-Tender-Document-1.pdf
... A436: 46194 | B436: 68 | G436: Request for Bid | H436: INVITATION TO A TENDER | I436: GREATKEILM.GOV.ZA | J436: Great Kei Local Municipality | K436: Eastern Cape | Q436: https://greatkeilm.gov.za/web/2026/06/09/invitation-to-a-tender-briefing/
...

Sheet Final
A1: Source | B1: Number of New Tenders | C1: ICT Tenders | D1: RFQs
A2: Report Date | B2: (M) 21/06/2026
A3: eTenders (All) | B3: =COUNTA('Tender Data'!J:J)-1 -> 502 | C3: =COUNTIF('Tender Data'!M:M,"Information service activities")+COUNTIF('Tender Data'!M:M,"Information and communication") -> 8 | D3: =COUNTIF('Tender Data'!G:G,"Request for Quotation") -> 91
A4: Eskom | B4: =COUNTIF('Tender Data'!J:J,"ESKOM") -> 22 | C4: =COUNTIFS('Tender Data'!M:M,"Information service activities",'Tender Data'!J:J,"ESKOM")+COUNTIFS('Tender Data'!M:M,"Information and communication",'Tender Data'!J:J,"ESKOM") -> 0 | D4: =COUNTIFS('Tender Data'!J:J,"ESKOM",'Tender Data'!G:G,"Request for Quotation") -> 1
A5: SITA | B5: =COUNTIF('Tender Data'!J:J,"State Information Technology Agency") -> 0 | C5: =COUNTIFS('Tender Data'!M:M,"Information service activities",'Tender Data'!J:J,"State Information Technology Agency")+COUNTIFS('Tender Data'!M:M,"Information and communication",'Tender Data'!J:J,"State Information Technology Agency") -> 0 | D5: =COUNTIFS('Tender Data'!J:J,"State Information Technology Agency",'Tender Data'!G:G,"Request for Quotation") -> 0
A6: Transnet | B6: =COUNTIF('Tender Data'!J:J,"Transnet*") -> 33 | C6: =COUNTIFS('Tender Data'!M:M,"Information service activities",'Tender Data'!J:J,"Transnet*")+COUNTIFS('Tender Data'!M:M,"Information and communication",'Tender Data'!J:J,"Transnet*") -> 0 | D6: =COUNTIFS('Tender Data'!J:J,"Transnet*",'Tender Data'!G:G,"Request for Quotation") -> 1
A7: JPC | B7: =COUNTIF('Tender Data'!J:J,"*Joburg Property*") -> 0 | C7: =COUNTIFS('Tender Data'!M:M,"Information service activities",'Tender Data'!J:J,"*Joburg Property*")+COUNTIFS('Tender Data'!M:M,"Information and communication",'Tender Data'!J:J,"*Joburg Property*") -> 0 | D7: =COUNTIFS('Tender Data'!J:J,"*Joburg Property*",'Tender Data'!G:G,"Request for Quotation") -> 0
A8: Matatiele LM | B8: =COUNTIF('Tender Data'!J:J,"Matatiele Local Municipality") -> 24 | C8: =COUNTIFS('Tender Data'!M:M,"Information service activities",'Tender Data'!J:J,"Matatiele Local Municipality")+COUNTIFS('Tender Data'!M:M,"Information and communication",'Tender Data'!J:J,"Matatiele Local Municipality") -> 0 | D8: =COUNTIFS('Tender Data'!J:J,"Matatiele Local Municipality",'Tender Data'!G:G,"Request for Quotation") -> 0
A9: Ntabankulu LM | B9: =COUNTIF('Tender Data'!J:J,"Ntabankulu Local Municipality") -> 12 | C9: =COUNTIFS('Tender Data'!M:M,"Information service activities",'Tender Data'!J:J,"Ntabankulu Local Municipality")+COUNTIFS('Tender Data'!M:M,"Information and communication",'Tender Data'!J:J,"Ntabankulu Local Municipality") -> 0 | D9: =COUNTIFS('Tender Data'!J:J,"Ntabankulu Local Municipality",'Tender Data'!G:G,"Request for Quotation") -> 0
A10: Umzimvubu LM | B10: =COUNTIF('Tender Data'!J:J,"Umzimvubu Local Municipality") -> 73 | C10: =COUNTIFS('Tender Data'!M:M,"Information service activities",'Tender Data'!J:J,"Umzimvubu Local Municipality")+COUNTIFS('Tender Data'!M:M,"Information and communication",'Tender Data'!J:J,"Umzimvubu Local Municipality") -> 0 | D10: =COUNTIFS('Tender Data'!J:J,"Umzimvubu Local Municipality",'Tender Data'!G:G,"Request for Quotation") -> 0
A11: Winnie Mandela LM | B11: =COUNTIF('Tender Data'!J:J,"Winnie Madikizela*") -> 2 | C11: =COUNTIFS('Tender Data'!M:M,"Information service activities",'Tender Data'!J:J,"Winnie Madikizela*")+COUNTIFS('Tender Data'!M:M,"Information and communication",'Tender Data'!J:J,"Winnie Madikizela*") -> 0 | D11: =COUNTIFS('Tender Data'!J:J,"Winnie Madikizela*",'Tender Data'!G:G,"Request for Quotation") -> 0
A12: Mnquma LM | B12: =COUNTIF('Tender Data'!J:J,"Mnquma Local Municipality") -> 0 | C12: =COUNTIFS('Tender Data'!M:M,"Information service activities",'Tender Data'!J:J,"Mnquma Local Municipality")+COUNTIFS('Tender Data'!M:M,"Information and communication",'Tender Data'!J:J,"Mnquma Local Municipality") -> 0 | D12: =COUNTIFS('Tender Data'!J:J,"Mnquma Local Municipality",'Tender Data'!G:G,"Request for Quotation") -> 0
A13: Great Kei LM | B13: =COUNTIF('Tender Data'!J:J,"Great Kei Local Municipality") -> 18 | C13: =COUNTIFS('Tender Data'!M:M,"Information service activities",'Tender Data'!J:J,"Great Kei Local Municipality")+COUNTIFS('Tender Data'!M:M,"Information and communication",'Tender Data'!J:J,"Great Kei Local Municipality") -> 0 | D13: =COUNTIFS('Tender Data'!J:J,"Great Kei Local Municipality",'Tender Data'!G:G,"Request for Quotation") -> 0
A14: Amahlathi LM | B14: =COUNTIF('Tender Data'!J:J,"Amahlathi Local Municipality") -> 1 | C14: =COUNTIFS('Tender Data'!M:M,"Information service activities",'Tender Data'!J:J,"Amahlathi Local Municipality")+COUNTIFS('Tender Data'!M:M,"Information and communication",'Tender Data'!J:J,"Amahlathi Local Municipality") -> 0 | D14: =COUNTIFS('Tender Data'!J:J,"Amahlathi Local Municipality",'Tender Data'!G:G,"Request for Quotation") -> 0
A15: Raymond Mhlaba LM | B15: =COUNTIF('Tender Data'!J:J,"Raymond Mhlaba Local Municipality") -> 0 | C15: =COUNTIFS('Tender Data'!M:M,"Information service activities",'Tender Data'!J:J,"Raymond Mhlaba Local Municipality")+COUNTIFS('Tender Data'!M:M,"Information and communication",'Tender Data'!J:J,"Raymond Mhlaba Local Municipality") -> 0 | D15: =COUNTIFS('Tender Data'!J:J,"Raymond Mhlaba Local Municipality",'Tender Data'!G:G,"Request for Quotation") -> 0
A16: JOSHCO | B16: =COUNTIF('Tender Data'!J:J,"*Johannesburg Social Housing*") -> 0 | C16: =COUNTIFS('Tender Data'!M:M,"Information service activities",'Tender Data'!J:J,"*Johannesburg Social Housing*")+COUNTIFS('Tender Data'!M:M,"Information and communication",'Tender Data'!J:J,"*Johannesburg Social Housing*") -> 0 | D16: =COUNTIFS('Tender Data'!J:J,"*Johannesburg Social Housing*",'Tender Data'!G:G,"Request for Quotation") -> 0
A17: GPL | B17: =COUNTIF('Tender Data'!J:J,"Gauteng Provincial Legislature") -> 1 | C17: =COUNTIFS('Tender Data'!M:M,"Information service activities",'Tender Data'!J:J,"Gauteng Provincial Legislature")+COUNTIFS('Tender Data'!M:M,"Information and communication",'Tender Data'!J:J,"Gauteng Provincial Legislature") -> 0 | D17: =COUNTIFS('Tender Data'!J:J,"Gauteng Provincial Legislature",'Tender Data'!G:G,"Request for Quotation") -> 1
A18: RAF | B18: =COUNTIF('Tender Data'!J:J,"Road Accident Fund") -> 4 | C18: =COUNTIFS('Tender Data'!M:M,"Information service activities",'Tender Data'!J:J,"Road Accident Fund")+COUNTIFS('Tender Data'!M:M,"Information and communication",'Tender Data'!J:J,"Road Accident Fund") -> 2 | D18: =COUNTIFS('Tender Data'!J:J,"Road Accident Fund",'Tender Data'!G:G,"Request for Quotation") -> 1
A19: MM Trading Company | B19: =COUNTIF('Tender Data'!J:J,"*Metropolitan Trading*") -> 0 | C19: =COUNTIFS('Tender Data'!M:M,"Information service activities",'Tender Data'!J:J,"*Metropolitan Trading*")+COUNTIFS('Tender Data'!M:M,"Information and communication",'Tender Data'!J:J,"*Metropolitan Trading*") -> 0 | D19: =COUNTIFS('Tender Data'!J:J,"*Metropolitan Trading*",'Tender Data'!G:G,"Request for Quotation") -> 0
A20: Nelson Mandela Bay MM | B20: =COUNTIF('Tender Data'!J:J,"*Nelson Mandela Bay*") -> 19 | C20: =COUNTIFS('Tender Data'!M:M,"Information service activities",'Tender Data'!J:J,"*Nelson Mandela Bay*")+COUNTIFS('Tender Data'!M:M,"Information and communication",'Tender Data'!J:J,"*Nelson Mandela Bay*") -> 0 | D20: =COUNTIFS('Tender Data'!J:J,"*Nelson Mandela Bay*",'Tender Data'!G:G,"Request for Quotation") -> 0
A21: Buffalo City MM | B21: =COUNTIF('Tender Data'!J:J,"*Buffalo City*") -> 1 | C21: =COUNTIFS('Tender Data'!M:M,"Information service activities",'Tender Data'!J:J,"*Buffalo City*")+COUNTIFS('Tender Data'!M:M,"Information and communication",'Tender Data'!J:J,"*Buffalo City*") -> 0 | D21: =COUNTIFS('Tender Data'!J:J,"*Buffalo City*",'Tender Data'!G:G,"Request for Quotation") -> 0
A22: EC DPW | B22: =COUNTIF('Tender Data'!J:J,"*Eastern Cape*Public Works*") -> 13 | C22: =COUNTIFS('Tender Data'!M:M,"Information service activities",'Tender Data'!J:J,"*Eastern Cape*Public Works*")+COUNTIFS('Tender Data'!M:M,"Information and communication",'Tender Data'!J:J,"*Eastern Cape*Public Works*") -> 0 | D22: =COUNTIFS('Tender Data'!J:J,"*Eastern Cape*Public Works*",'Tender Data'!G:G,"Request for Quotation") -> 2
A23: DEL | B23: =COUNTIF('Tender Data'!J:J,"*Labour*") -> 4 | C23: =COUNTIFS('Tender Data'!M:M,"Information service activities",'Tender Data'!J:J,"*Labour*")+COUNTIFS('Tender Data'!M:M,"Information and communication",'Tender Data'!J:J,"*Labour*") -> 0 | D23: =COUNTIFS('Tender Data'!J:J,"*Labour*",'Tender Data'!G:G,"Request for Quotation") -> 1
A24: SIU | B24: =COUNTIF('Tender Data'!J:J,"Special Investigation Unit*") -> 0 | C24: =COUNTIFS('Tender Data'!M:M,"Information service activities",'Tender Data'!J:J,"Special Investigation Unit*")+COUNTIFS('Tender Data'!M:M,"Information and communication",'Tender Data'!J:J,"Special Investigation Unit*") -> 0 | D24: =COUNTIFS('Tender Data'!J:J,"Special Investigation Unit*",'Tender Data'!G:G,"Request for Quotation") -> 0
A25: GDoH | B25: =COUNTIF('Tender Data'!J:J,"*Gauteng*Health*") -> 4 | C25: =COUNTIFS('Tender Data'!M:M,"Information service activities",'Tender Data'!J:J,"*Gauteng*Health*")+COUNTIFS('Tender Data'!M:M,"Information and communication",'Tender Data'!J:J,"*Gauteng*Health*") -> 0 | D25: =COUNTIFS('Tender Data'!J:J,"*Gauteng*Health*",'Tender Data'!G:G,"Request for Quotation") -> 0
A26: DIRCO | B26: =COUNTIF('Tender Data'!J:J,"*International Relation*") -> 0 | C26: =COUNTIFS('Tender Data'!M:M,"Information service activities",'Tender Data'!J:J,"*International Relation*")+COUNTIFS('Tender Data'!M:M,"Information and communication",'Tender Data'!J:J,"*International Relation*") -> 0 | D26: =COUNTIFS('Tender Data'!J:J,"*International Relation*",'Tender Data'!G:G,"Request for Quotation") -> 0
A27: DOJ | B27: =COUNTIF('Tender Data'!J:J,"*Justice*Constitutional*") -> 0 | C27: =COUNTIFS('Tender Data'!M:M,"Information service activities",'Tender Data'!J:J,"*Justice*Constitutional*")+COUNTIFS('Tender Data'!M:M,"Information and communication",'Tender Data'!J:J,"*Justice*Constitutional*") -> 0 | D27: =COUNTIFS('Tender Data'!J:J,"*Justice*Constitutional*",'Tender Data'!G:G,"Request for Quotation") -> 0
A28: CP JHB | B28: =COUNTIF('Tender Data'!J:J,"City Power*Johannesburg*") -> 0 | C28: =COUNTIFS('Tender Data'!M:M,"Information service activities",'Tender Data'!J:J,"City Power*Johannesburg*")+COUNTIFS('Tender Data'!M:M,"Information and communication",'Tender Data'!J:J,"City Power*Johannesburg*") -> 0 | D28: =COUNTIFS('Tender Data'!J:J,"City Power*Johannesburg*",'Tender Data'!G:G,"Request for Quotation") -> 0
A29: W JHB | B29: =COUNTIF('Tender Data'!J:J,"*Johannesburg Water*") -> 15 | C29: =COUNTIFS('Tender Data'!M:M,"Information service activities",'Tender Data'!J:J,"*Johannesburg Water*")+COUNTIFS('Tender Data'!M:M,"Information and communication",'Tender Data'!J:J,"*Johannesburg Water*") -> 0 | D29: =COUNTIFS('Tender Data'!J:J,"*Johannesburg Water*",'Tender Data'!G:G,"Request for Quotation") -> 11
B30: =SUM(B4:B29) -> 246 | C30: =SUM(C4:C29) -> 2 | D30: =SUM(D4:D29) -> 18

Sheet Raw Data
A1: REPORT_DATE | B1: RECORD_ID | C1: TENDER_ID | D1: PUBLICATION_DATE | E1: CLOSING_DATE | F1: CLOSING_TIME | G1: TENDER_TYPE | H1: TENDER_DESCRIPTION | I1: TENDER_SOURCE | J1: DEPARTMENT | K1: PROVINCE | L1: ESUBMISSION | M1: CATEGORY | N1: IS_THERE_A_BRIEFING_SESSION | O1: COMPULSORY_BRIEFING | P1: BRIEFING_SESSION_VENUE | Q1: LINK | R1: SOE | S1: COST_OF_SALES_ESTIMATE | T1: CAPABILITY_AVAILABLE | U1: CAPABILITY_GROUP | V1: REQUIREMENTS
A2: 46191 | B2: 639 | C2: CO 26/12 O | D2: 46191 | E2: 46230 | F2: 12:00 | G2: Request for Bid(Open-Tender) | H2: Provision of Grounds and Gardening Services at Majuba TVET College for a period of 5 Years | I2: ETENDERS.GOV.ZA | J2: Majuba Tvet college | K2: KwaZulu-Natal | L2: No | M2: Other service activities | N2: Yes | O2: Yes | P2: Newcastle Training Centre Hall, 2 HJ Van Eck Avenue, Newcastle | Q2: https://www.etenders.gov.za/home/Download/?blobName=1debbfd3-bfd5-48cc-9819-dab8ebf24933.pdf&downloadedFileName=Advert%20for%20PROVISION%20OF%20GROUND%20AND%20GARDENING%20SERVICES%20AT%20MAJUBA%20TVET%20COLLEGE%20SITES%20FOR%20THE%20PERIOD%20OF%20(05)%20YEARS.pdf
A3: 46191 | B3: 638 | C3: IT 26/03 C | D3: 46191 | E3: 46230 | F3: 12:00 | G3: Request for Bid(Open-Tender) | H3: Provision of Endpoint Protection and XDR Security Solution at Majuba TVET College for the period of five (05) Years | I3: ETENDERS.GOV.ZA | J3: Majuba Tvet college | K3: KwaZulu-Natal | L3: No | M3: Information and communication | N3: Yes | O3: Yes | P3: Virtual meeting - the link will be shared with service providers that requested for the document | Q3: https://www.etenders.gov.za/home/Download/?blobName=3e0a07c5-0aab-491e-8cd4-3b631e78b5b1.pdf&downloadedFileName=Advert%20for%20Provision%20of%20internet%20services%20-%20End%20Point-%203%20Tier.pdf
A4: 46191 | B4: 637 | C4: GMT061/25-26 | D4: 46191 | E4: 46230 | F4: 12:00 | G4: Request for Bid(Open-Tender) | H4: Appointment of a Panel of Contractors to attend to Plumbing Related Services for Municipal Buildings and Facilities, Informal Settlement Areas and Indigent Households, as and when required, for a period of three (3) years from date of appointment until 30 June 2029 | I4: ETENDERS.GOV.ZA | J4: George Municipality | K4: Western Cape | L4: No | M4: Other service activities | N4: Yes | O4: Yes | P4: Conference Hall at George Municipality’s Civic Centre, York Street, George | Q4: https://www.etenders.gov.za/home/Download/?blobName=822effce-63d3-4ef3-b75c-03cdcac572ce.pdf&downloadedFileName=GMT061%20of%2025-26%20Tender%20document_18%20June%202026_%20Final.pdf
A5: 46191 | B5: 636 | C5: NKO10/2026 | D5: 46191 | E5: 46234 | F5: 12:00 | G5: Request for Bid(Open-Tender) | H5: APPOINTMENT OF A SUITABLE SERVICE PROVIDER FOR SUPPLY AND DELIVERY OF PROTECTIVE CLOTHING AND RELATED ITEMS FOR NKOMAZI LOCAL MUNICIPALITY FOR A PERIOD OF THREE YEARS (36 MONTHS) | I5: ETENDERS.GOV.ZA | J5: Nkomazi Local Municipality | K5: Mpumalanga | L5: No | M5: Supplies: Clothing/Textiles/Footwear | N5: Yes | O5: Yes | P5: Municipal Town Hall (Kobwa), Fish Eagle, Malalane | Q5: https://www.etenders.gov.za/home/Download/?blobName=f2432ad0-77b3-4217-aace-6ab28d55ed7a.pdf&downloadedFileName=NKO%2010%202026.pdf
A6: 46191 | B6: 635 | C6: IT 26/03 O | D6: 46191 | E6: 46226 | F6: 12:00 | G6: Request for Bid(Open-Tender) | H6: Provision of Internet Services at Majuba TVET College for the period of five(05) Years | I6: ETENDERS.GOV.ZA | J6: Majuba Tvet college | K6: KwaZulu-Natal | L6: No | M6: Information and communication | N6: Yes | O6: Yes | P6: 83 Allen Street, Newcastle | Q6: https://www.etenders.gov.za/home/Download/?blobName=aa42ef56-627e-43ee-8472-b8b52e5ca98b.pdf&downloadedFileName=Advert%20for%20Provision%20of%20internet%20services%20-%20End%20Point-%203%20Tier.pdf
A7: 46191 | B7: 634 | C7: IT 26/02 O | D7: 46191 | E7: 46226 | F7: 12:00 | G7: Request for Bid(Open-Tender) | H7: Provision of 3 Tier Virtual Environment at Majuba TVET College for the Period of (05) Five Years | I7: ETENDERS.GOV.ZA | J7: Majuba Tvet college | K7: KwaZulu-Natal | L7: No | M7: Information and communication | N7: Yes | O7: Yes | P7: 83 Allen Street, Newcastle | Q7: https://www.etenders.gov.za/home/Download/?blobName=ab8110d3-d32a-4e46-9514-4dade2be3b29.pdf&downloadedFileName=Advert%20for%20Provision%20of%20internet%20services%20-%20End%20Point-%203%20Tier.pdf
A8: 46191 | B8: 633 | C8: MDM 2025/26 -54 | D8: 46191 | E8: 46225 | F8: 12:00 | G8: Request for Bid(Open-Tender) | H8: Giyani Water Reticulation Phase 2A(Contract 014)-Mushiyani Water Reticulation | I8: ETENDERS.GOV.ZA | J8: Mopani District Municipality | K8: Limpopo | L8: No | M8: Civil engineering | N8: No | O8: No | P8: N/A | Q8: https://www.etenders.gov.za/home/Download/?blobName=3de493a7-77b0-4082-93f7-5392f24917ed.pdf&downloadedFileName=Giyani%20Water%20Reticulation%20to%20Villages%20Phase%202A%20-%20Final%20advert%20.pdf
A9: 46191 | B9: 632 | C9: MDM 2025/26 -55 | D9: 46191 | E9: 46225 | F9: 12:00 | G9: Request for Bid(Open-Tender) | H9: Giyani Water Reticulation Phase 2A(Contract 015)-Nsavulani Water Reticulation | I9: ETENDERS.GOV.ZA | J9: Mopani District Municipality | K9: Limpopo | L9: No | M9: Civil engineering | N9: No | O9: No | P9: N/A | Q9: https://www.etenders.gov.za/home/Download/?blobName=ff75eedc-33dd-4422-ad80-c8b5c3edd20d.pdf&downloadedFileName=Giyani%20Water%20Reticulation%20to%20Villages%20Phase%202A%20-%20Final%20advert%20.pdf
A10: 46191 | B10: 631 | C10: MDM 2025/26 -56 | D10: 46191 | E10: 46225 | F10: 12:00 | G10: Request for Bid(Open-Tender) | H10: Giyani Water Reticulation Phase 2A(Contract 016)-Nwadzekudzeku Water Reticulation | I10: ETENDERS.GOV.ZA | J10: Mopani District Municipality | K10: Limpopo | L10: No | M10: Civil engineering | N10: No | O10: No | P10: N/A | Q10: https://www.etenders.gov.za/home/Download/?blobName=6c20d68c-60b4-4bd6-bec6-d223d4334480.pdf&downloadedFileName=Giyani%20Water%20Reticulation%20to%20Villages%20Phase%202A%20-%20Final%20advert%20.pdf
A11: 46191 | B11: 630 | C11: MDM 2025/26 -57 | D11: 46191 | E11: 46225 | F11: 12:00 | G11: Request for Bid(Open-Tender) | H11: Giyani Water Reticulation Phase 2A(Contract 017)-Phlaubeni Water Reticulation | I11: ETENDERS.GOV.ZA | J11: Mopani District Municipality | K11: Limpopo | L11: No | M11: Civil engineering | N11: No | O11: No | P11: N/A | Q11: https://www.etenders.gov.za/home/Download/?blobName=e0fd5d6a-ebc0-4d41-8d0b-e7da53144af0.pdf&downloadedFileName=Giyani%20Water%20Reticulation%20to%20Villages%20Phase%202A%20-%20Final%20advert%20.pdf
A12: 46191 | B12: 629 | C12: MDM 2025/26 -58 | D12: 46191 | E12: 46225 | F12: 12:00 | G12: Request for Bid(Open-Tender) | H12: Giyani Water Reticulation Phase 2A(Contract 018)-Vuhehli Water Reticulation Contract B | I12: ETENDERS.GOV.ZA | J12: Mopani District Municipality | K12: Limpopo | L12: No | M12: Civil engineering | N12: No | O12: No | P12: N/A | Q12: https://www.etenders.gov.za/home/Download/?blobName=0d05656e-3662-4857-adb5-1edf132c6906.pdf&downloadedFileName=Giyani%20Water%20Reticulation%20to%20Villages%20Phase%202A%20-%20Final%20advert%20.pdf
A13: 46191 | B13: 628 | C13: MDM 2025/26 -59 | D13: 46191 | E13: 46225 | F13: 12:00 | G13: Request for Bid(Open-Tender) | H13: Giyani Water Reticulation Phase 2A(Contract 019)-Xikhumba Water Reticulation Contract A | I13: ETENDERS.GOV.ZA | J13: Mopani District Municipality | K13: Limpopo | L13: No | M13: Civil engineering | N13: No | O13: No | P13: N/A | Q13: https://www.etenders.gov.za/home/Download/?blobName=6259c7a5-5913-45da-ac0a-0c6715b34390.pdf&downloadedFileName=Giyani%20Water%20Reticulation%20to%20Villages%20Phase%202A%20-%20Final%20advert%20.pdf
... A337: 46194 | B337: 304 | C337: Table 01 | D337: 46194 | E337: 46198 | F337: 10:00 | G337: Request for Quotation | H337: Supply and delivery of Boardroom table | I337: ETENDERS.GOV.ZA | J337: South African Nuclear Energy Corporation Limited | K337: North West | L337: No | M337: Manufacture of furniture | N337: No | O337: No | P337: N/A | Q337: https://www.etenders.gov.za/home/Download/?blobName=f329ec1e-7fd4-4245-af1d-3b7843d6cfaf.docx&downloadedFileName=RFQ%20number%20Tables%2001.docx
A338: 46196 | B338: 303 | C338: BCM5-26/27-0013 | D338: 46196 | E338: 46205 | F338: 11:00 | G338: Request for Quotation | H338: QUOTATION FOR THE APPOINTMENT OF A SUITABLE SERVICE PROVIDER TO RENDER TRAINING SERVICES FOR MASTERING ENGINEERING AND CONSTRUCTION CONTRACTS FOR EIGHT (08) OFFICIALS AS PER SPECIFICATION TO THE EASTERN CAPE DEPARTMENT OF PUBLIC WORKS & INFRASTRUCTURE | I338: ECDPW.GOV.ZA | J338: Eastern Cape Department of Public Works and Infrastructure | K338: Eastern Cape | Q338: https://www.ecdpw.gov.za/wp-content/tender-uploads/bcm5-2627-0013.pdf
A339: 46196 | B339: 302 | C339: SCMU5-26/27-0035 | D339: 46195 | E339: 46210 | F339: 11:00 | G339: Request for Bid | H339: APPOINTMENT OF SERVICE PROVIDER FOR THE PROVISION OF ADEQUATE OFFICE ACCOMMODATION WITHIN MTHATHA CENTRAL BUSINESS DISTRICT - DEPARTMENT OF AGRICULTURE | I339: ECDPW.GOV.ZA | J339: Eastern Cape Department of Public Works and Infrastructure | K339: Eastern Cape | Q339: https://www.ecdpw.gov.za/wp-content/tender-uploads/department-of-agriculture--mthatha-cbd--final-0035.pdf
A340: 46196 | B340: 301 | C340: SCMU5-26/27-0034 | D340: 46195 | E340: 46210 | F340: 11:00 | G340: Request for Bid | H340: APPOINTMENT OF SERVICE PROVIDER FOR THE PROVISION OF ADEQUATE OFFICE ACCOMMODATION WITHIN MTHATHA CENTRAL BUSINESS DISTRICT - DEPARTMENT OF SOCIAL DEVELOPMENT: DISTRICT OFFICE | I340: ECDPW.GOV.ZA | J340: Eastern Cape Department of Public Works and Infrastructure | K340: Eastern Cape | Q340: https://www.ecdpw.gov.za/wp-content/tender-uploads/department-of-social-development-district-office--mthatha-cbd--final-0034.pdf
A341: 46196 | B341: 300 | C341: SCMU5-26/27-0029 | D341: 46195 | E341: 46224 | G341: Request for Bid | H341: TAFALOFEFE HOSPITAL: WATER AND WASTEWATER TREATMENT WORKS | I341: ECDPW.GOV.ZA | J341: Eastern Cape Department of Public Works and Infrastructure | K341: Eastern Cape | Q341: https://www.ecdpw.gov.za/wp-content/tender-uploads/scmu5-2627-0029_-tafalofefe-hospital--water-and-wastewater-treatment-works-.pdf
A342: 46196 | B342: 299 | C342: SCMU5-26/27-0033 | D342: 46195 | E342: 46210 | F342: 11:00 | G342: Request for Bid | H342: APPOINTMENT OF SERVICE PROVIDER FOR THE PROVISION OF ADEQUATE OFFICE ACCOMMODATION WITHIN MTHATHA CENTRAL BUSINESS DISTRICT - DEPARTMENT OF TRANSPORT | I342: ECDPW.GOV.ZA | J342: Eastern Cape Department of Public Works and Infrastructure | K342: Eastern Cape | Q342: https://www.ecdpw.gov.za/wp-content/tender-uploads/department-of-transport--mthatha-cbd--final-0033.pdf
A343: 46196 | B343: 298 | C343: SCMU5-26/27-0032 | D343: 46195 | E343: 46210 | F343: 11:00 | G343: Request for Bid | H343: APPOINTMENT OF SERVICE PROVIDER FOR THE PROVISION OF ADEQUATE OFFICE ACCOMMODATION WITHIN MTHATHA CENTRAL BUSINESS DISTRICT - DEPARTMENT OF SOCIAL DEVELOPMENT: LOCAL AREA OFFICE | I343: ECDPW.GOV.ZA | J343: Eastern Cape Department of Public Works and Infrastructure | K343: Eastern Cape | Q343: https://www.ecdpw.gov.za/wp-content/tender-uploads/department-of-social-development-local-area-office--mthatha-cbd--final-0032.pdf
A344: 46196 | B344: 297 | C344: SCMU5-26/27-0009 | D344: 46195 | G344: Request for Bid | H344: ERRATUM: TERM CONTRACT FOR MANAGEMENT AND ADMINISTERING PAYMENT OF MONTHLYSTIPEND FOR EPWP PARTICIPANTS FOR A PERIOD OF 3 YEARS. | I344: ECDPW.GOV.ZA | J344: Eastern Cape Department of Public Works and Infrastructure | K344: Eastern Cape | Q344: https://www.ecdpw.gov.za/wp-content/tender-uploads/erratum-scmu5-26-27-0009.pdf
A345: 46196 | B345: 296 | C345: SCMU5-26/27-0002 | D345: 46195 | E345: 46238 | F345: 14:00 | G345: Request for Bid | H345: EXPRESSION OF INTEREST FOR A PANEL OF TRAINING PROVIDERS FOR EPWP PROGRAMMES FOR A PERIOD OF THREE (3) YEARS. | I345: ECDPW.GOV.ZA | J345: Eastern Cape Department of Public Works and Infrastructure | K345: Eastern Cape | Q345: https://www.ecdpw.gov.za/wp-content/tender-uploads/0002-9.pdf
A346: 46196 | B346: 295 | C346: SCMU5-26/27-0022 | D346: 46195 | E346: 46224 | F346: 11:00 | G346: Request for Bid | H346: BID FOR THE APPOINTMENT OF SERVICE PROVIDER FOR THE RENEWAL OF SUPPORT AND MAINTENANCE FOR DISASTER RECOVERY AND MANAGED BACKUP SERVICES INCLUDING LICENSES FOR A PERIOD OF 24 MONTHS AS PER SPECIFICATION | I346: ECDPW.GOV.ZA | J346: Eastern Cape Department of Public Works and Infrastructure | K346: Eastern Cape | Q346: https://www.ecdpw.gov.za/wp-content/tender-uploads/scmu5-26-27-0022.pdf
A347: 46196 | B347: 294 | C347: BCM5-26/27-0012 | D347: 46192 | E347: 46196 | F347: 11:00 | G347: Request for Quotation | H347: QUOTATION FOR SUPPLY, DELIVERY AND DECANTING OF DIESEL AT AMALINDA OFFICES AS PER SPECIFICATION FROM DEPARTMENT OF PUBLIC WORKS AND INFRASTRUCTURE | I347: ECDPW.GOV.ZA | J347: Eastern Cape Department of Public Works and Infrastructure | K347: Eastern Cape | Q347: https://www.ecdpw.gov.za/wp-content/tender-uploads/bcm5-26-27-0012-quotation-for-supply-delivery-and-decanting-of-diesel-at---amalinda-offices-as-per-specification-from-department-of-public-works-and-infrastructure-.pdf
A348: 46196 | B348: 293 | C348: ALF5-26/27-0004 | D348: 46192 | E348: 46216 | F348: 11:00 | G348: Request for Bid | H348: TWO YEAR TERM CONTRACT FOR SUPPLY, SERVICING, REPAIRS AND MAINTENANCE OF GENERAL BUILDING FOR ALFRED NZO DISTRICT | I348: ECDPW.GOV.ZA | J348: Eastern Cape Department of Public Works and Infrastructure | K348: Eastern Cape | Q348: https://www.ecdpw.gov.za/wp-content/tender-uploads/alf5-26-27-0004-term-contract-gaeneral-building.pdf
A349: 46196 | B349: 292 | C349: ALF5-26/27-0003 | D349: 46192 | E349: 46213 | F349: 11:00 | G349: Request for Bid | H349: TWO YEAR TERM CONTRACT FOR SUPPLY, SERVICING, REPAIRS AND MAINTENANCE OF PLUMBING AND DRAINAGE EQUIPMENT IN ALFRED NZO DISTRICT | I349: ECDPW.GOV.ZA | J349: Eastern Cape Department of Public Works and Infrastructure | K349: Eastern Cape | Q349: https://www.ecdpw.gov.za/wp-content/tender-uploads/alf5-26-27-0003-term-contract-plumbing.pdf
A350: 46196 | B350: 291 | C350: ALF5-26/27-0002 | D350: 46192 | E350: 46213 | F350: 11:00 | G350: Request for Bid | H350: TWO YEAR TERM CONTRACT FOR SUPPLY, SERVICING, REPAIRS AND MAINTENANCE OF ELECTRICAL EQUIPMENT FOR ALFRED NZO DISTRICT | I350: ECDPW.GOV.ZA | J350: Eastern Cape Department of Public Works and Infrastructure | K350: Eastern Cape | Q350: https://www.ecdpw.gov.za/wp-content/tender-uploads/alf5-26-27-0002-term-contract-electical.pdf
A351: 46194 | B351: 290 | G351: Request for Bid | H351: Training on People 300 Skills Development and Emplyment Equity for 5 Employees | I351: NTABANKULU.GOV.ZA | J351: Ntabankulu Local Municipality | K351: Eastern Cape | Q351: https://www.ntabankulu.gov.za/2026/06/19/training-on-people-300-skills-development-and-emplyment-equity-for-5-employees/
A352: 46194 | B352: 289 | G352: Request for Bid | H352: Bid Invitation for Construction of Tsweleni AR and Gxwaleni Concrete Slab | I352: NTABANKULU.GOV.ZA | J352: Ntabankulu Local Municipality | K352: Eastern Cape | Q352: https://www.ntabankulu.gov.za/2026/06/19/bid-invitation-for-construction-of-tsweleni-ar-and-gxwaleni-concrete-slab/
A353: 46194 | B353: 288 | G353: Request for Bid | H353: CLOSING REGISTER FOR SUPPLY AND DELIVERY OF DIESEL | I353: NTABANKULU.GOV.ZA | J353: Ntabankulu Local Municipality | K353: Eastern Cape | Q353: https://www.ntabankulu.gov.za/2026/06/17/closing-register-for-supply-and-delivery-of-diesel/
A354: 46194 | B354: 287 | G354: Request for Bid | H354: CLOSING REGISTER FOR PROVISION OF SECURITY SERVICES | I354: NTABANKULU.GOV.ZA | J354: Ntabankulu Local Municipality | K354: Eastern Cape | Q354: https://www.ntabankulu.gov.za/2026/06/17/closing-register-for-provision-of-security-services/
A355: 46194 | B355: 286 | G355: Request for Bid | H355: TENDER DOCUMENTFOR 3 YEAR FRAMEWORK CONTRACT OF 05 ROAD MAINTENANCE CONTRACTORS | I355: NTABANKULU.GOV.ZA | J355: Ntabankulu Local Municipality | K355: Eastern Cape | Q355: https://www.ntabankulu.gov.za/2026/06/10/tender-documentfor-3-year-framework-contract-of-05-road-maintenance-contractors/
A356: 46194 | B356: 285 | G356: Request for Bid | H356: Closing Register for Construction of Fenced Mathole Pre-School with Ablution Facilities | I356: NTABANKULU.GOV.ZA | J356: Ntabankulu Local Municipality | K356: Eastern Cape | Q356: https://www.ntabankulu.gov.za/2026/06/03/closing-register-for-construction-of-fenced-mathole-pre-school-with-ablution-facilities/
A357: 46194 | B357: 284 | G357: Request for Bid | H357: Bid Invitation for Electrification and Maintenance Contractors | I357: NTABANKULU.GOV.ZA | J357: Ntabankulu Local Municipality | K357: Eastern Cape | Q357: https://www.ntabankulu.gov.za/2026/05/29/bid-invitation-for-electrification-and-maintenance-contractors/
A358: 46194 | B358: 283 | G358: Request for Bid | H358: Supply and Delivery of Kid’s Learning Gadgets | I358: NTABANKULU.GOV.ZA | J358: Ntabankulu Local Municipality | K358: Eastern Cape | Q358: https://www.ntabankulu.gov.za/2026/05/29/supply-and-delivery-of-kids-learning-gadgets-2/
A359: 46194 | B359: 282 | G359: Request for Bid | H359: Closing Register for Construction of Rwantsana Community Hall | I359: NTABANKULU.GOV.ZA | J359: Ntabankulu Local Municipality | K359: Eastern Cape | Q359: https://www.ntabankulu.gov.za/2026/05/26/closing-register-for-construction-of-rwantsana-community-hall/
A360: 46194 | B360: 281 | G360: Request for Bid | H360: Supply and Delivery of Diesel for 12 Months | I360: NTABANKULU.GOV.ZA | J360: Ntabankulu Local Municipality | K360: Eastern Cape | Q360: https://www.ntabankulu.gov.za/2026/05/21/supply-and-delivery-of-diesel-for-12-months/
A361: 46194 | B361: 280 | G361: Request for Bid | H361: WEBSITE HOSTING AND MAINTENANCE SERVICES FOR UMZIMVUBU LOCAL MUNICIPALITY FOR A PERIOD OF 3 YEARS (1) | I361: UMZIMVUBU.GOV.ZA | J361: Umzimvubu Local Municipality | K361: Eastern Cape | Q361: https://www.umzimvubu.gov.za/wp-content/uploads/2025/02/WEBSITE-HOSTING-AND-MAINTENANCE-SERVICES-FOR-UMZIMVUBU-LOCAL-MUNICIPALITY-FOR-A-PERIOD-OF-3-YEARS-1.pdf
A362: 46194 | B362: 279 | G362: Request for Bid | H362: Umndini Tender Document 1 | I362: UMZIMVUBU.GOV.ZA | J362: Umzimvubu Local Municipality | K362: Eastern Cape | Q362: https://www.umzimvubu.gov.za/wp-content/uploads/2025/02/Umndini-Tender-Document-1.pdf
... A434: 46194 | B434: 207 | G434: Request for Bid | H434: WMM LM MBD FORMS 2023.pdf | I434: WINNIEMMLM.GOV.ZA | J434: Winnie Madikizela-Mandela Local Municipality | K434: Eastern Cape | Q434: https://www.winniemmlm.gov.za/wp-content/uploads/2023/02/WMM-LM-MBD-FORMS-2023.pdf.pdf
...
